Workbook

Sheet Schedule 2026
A1: COMPANY NAME: Popeyes | J1: =SUM(I20,J20,L20,W20:X20) -> 1785.85 | X1: Prepared by: | Y1: Caleb Vega | AA1: SELECT MONTH:
A2: COMPANY: QCJ - QMSI | AA2: P08
A3: GL ACCOUNT NAME: PERSONAL PROPERTY TAX
A4: GL ACCOUNT #: 138500 | X4: =SUM(L9:Q9) -> -2382.9
A5: YEAR: 2026
L6: January | M6: February | N6: March | O6: April | P6: May | Q6: June | R6: July | S6: August | T6: September | U6: October | V6: November | W6: December | AA6: ="Balance as of "&TEXT(EOMONTH(DATE(2026,VALUE(MID($AA$2,2,2)),1),0),"MM/DD/YYYY") -> Balance as of 08/31/YYYY
A7: Payee | B7: Location | C7: Entity | D7: GL Acct | E7: DOC | F7: Exp. To GL Acct | G7: Date | H7: Amortization Period | I7: Amount Paid | J7: Prior Yr End Balance Forward | K7: MO AMORT AMT | L7: P01.26 | M7: P02.26 | N7: P03.26 | O7: P04.26 | P7: P05.26 | Q7: P06.26 | R7: P07.26 | S7: P08.26 | T7: P09.26 | U7: P10.26 | V7: P11.26 | W7: P12.26 | X7: YTD Amortization | Y7: Ending Prepaid Balance | Z7: ENDING BAL PER STORE | AA7: Balance as of Period
A8: Entity: QCJ | C8: QCJ | L8: 0 | M8: 0 | N8: 0 | O8: 0 | P8: 0 | Q8: 0 | R8: 0 | S8: 0 | X8: {=SUMPRODUCT((LEFT($L$7:$W$7,3)<=$AA$2)*L8:W8)} -> 0 | Y8: =IF(Schedule3[[#This Row],[Prior Yr End Balance Forward]]<>"",Schedule3[[#This Row],[Prior Yr End Balance Forward]]+SUM(Schedule3[[#This Row],[P01.26]:[P12.26]]),Schedule3[[#This Row],[Amount Paid]]+SUM(Schedule3[[#This Row],[P01.26]:[P12.26]])) -> 0 | Z8: =IF(OR(B8<>B9,D8<>D9),SUMIFS(AA:AA,B:B,B8,D:D,D8),"") -> 0 | AA8: {=IF(Schedule3[[#This Row],[GL Acct]]=232000,Schedule3[[#This Row],[Prior Yr End Balance Forward]]+Schedule3[[#This Row],[YTD Amortization]],IF(OR(Schedule3[[#This Row],[Date ]]="", Schedule3[[#This Row],[Date ]]>EOMONTH(DATE(2026,VALUE(MID($AA$2,2,2)),1),0)), Schedule3[[#This Row],[P01.26]], IF(Schedule3[[#This Row],[Prior Yr End Balance Forward]]<>"", Schedule3[[#This Row],[Prior Yr End Balance Forward]], IF(Schedule3[[#This Row],[Amount Paid]]<>"",Schedule3[[#This Row],[Amount Paid]],0))+SUMPRODUCT((COLUMN(Schedule3[[#This Row],[P01.26]]:Schedule3[[#This Row],[P12.26]])<=COLUMN(INDIRECT("Schedule3[P"&MID($AA$2,2,2)&".26]")))*Schedule3[[#This Row],[P01.26]]:Schedule3[[#This Row],[P12.26]])))} -> 0
A9: Sacramento County PPTaxes | B9: 2902 | C9: QCJ | D9: 138500 | F9: 708500 | G9: 45903 | H9: 09/01/25 - 08/31/26 | I9: 4765.83 | J9: 3177.22 | K9: 397.15 | L9: -397.15 | M9: -397.15 | N9: -397.15 | O9: -397.15 | P9: -397.15 | Q9: -397.15 | R9: -397.15 | S9: -397.17 | X9: {=SUMPRODUCT((LEFT($L$7:$W$7,3)<=$AA$2)*L9:W9)} -> -3177.22 | Y9: =IF(Schedule3[[#This Row],[Prior Yr End Balance Forward]]<>"",Schedule3[[#This Row],[Prior Yr End Balance Forward]]+SUM(Schedule3[[#This Row],[P01.26]:[P12.26]]),Schedule3[[#This Row],[Amount Paid]]+SUM(Schedule3[[#This Row],[P01.26]:[P12.26]])) -> 0 | Z9: =IF(OR(B9<>B10,D9<>D10),SUMIFS(AA:AA,B:B,B9,D:D,D9),"") -> 0 | AA9: {=IF(Schedule3[[#This Row],[GL Acct]]=232000,Schedule3[[#This Row],[Prior Yr End Balance Forward]]+Schedule3[[#This Row],[YTD Amortization]],IF(OR(Schedule3[[#This Row],[Date ]]="", Schedule3[[#This Row],[Date ]]>EOMONTH(DATE(2026,VALUE(MID($AA$2,2,2)),1),0)), Schedule3[[#This Row],[P01.26]], IF(Schedule3[[#This Row],[Prior Yr End Balance Forward]]<>"", Schedule3[[#This Row],[Prior Yr End Balance Forward]], IF(Schedule3[[#This Row],[Amount Paid]]<>"",Schedule3[[#This Row],[Amount Paid]],0))+SUMPRODUCT((COLUMN(Schedule3[[#This Row],[P01.26]]:Schedule3[[#This Row],[P12.26]])<=COLUMN(INDIRECT("Schedule3[P"&MID($AA$2,2,2)&".26]")))*Schedule3[[#This Row],[P01.26]]:Schedule3[[#This Row],[P12.26]])))} -> 0
A10: Sacramento County PPTaxes | B10: 4579 | C10: QCJ | D10: 138500 | F10: 708500 | G10: 45903 | H10: 09/01/25 - 08/31/26 | I10: 5966.56 | J10: 3977.71 | K10: 497.21 | L10: -497.21 | M10: -497.21 | N10: -497.21 | O10: -497.21 | P10: -497.21 | Q10: -497.21 | R10: -497.21 | S10: -497.24 | X10: {=SUMPRODUCT((LEFT($L$7:$W$7,3)<=$AA$2)*L10:W10)} -> -3977.71 | Y10: =IF(Schedule3[[#This Row],[Prior Yr End Balance Forward]]<>"",Schedule3[[#This Row],[Prior Yr End Balance Forward]]+SUM(Schedule3[[#This Row],[P01.26]:[P12.26]]),Schedule3[[#This Row],[Amount Paid]]+SUM(Schedule3[[#This Row],[P01.26]:[P12.26]])) -> 0 | Z10: =IF(OR(B10<>B11,D10<>D11),SUMIFS(AA:AA,B:B,B10,D:D,D10),"") -> 0 | AA10: {=IF(Schedule3[[#This Row],[GL Acct]]=232000,Schedule3[[#This Row],[Prior Yr End Balance Forward]]+Schedule3[[#This Row],[YTD Amortization]],IF(OR(Schedule3[[#This Row],[Date ]]="", Schedule3[[#This Row],[Date ]]>EOMONTH(DATE(2026,VALUE(MID($AA$2,2,2)),1),0)), Schedule3[[#This Row],[P01.26]], IF(Schedule3[[#This Row],[Prior Yr End Balance Forward]]<>"", Schedule3[[#This Row],[Prior Yr End Balance Forward]], IF(Schedule3[[#This Row],[Amount Paid]]<>"",Schedule3[[#This Row],[Amount Paid]],0))+SUMPRODUCT((COLUMN(Schedule3[[#This Row],[P01.26]]:Schedule3[[#This Row],[P12.26]])<=COLUMN(INDIRECT("Schedule3[P"&MID($AA$2,2,2)&".26]")))*Schedule3[[#This Row],[P01.26]]:Schedule3[[#This Row],[P12.26]])))} -> 0
A11: Alameda County PPTaxes | B11: 5328 | C11: QCJ | D11: 138500 | F11: 708500 | G11: 45903 | H11: 09/01/25 - 08/31/26 | I11: 1413.7 | J11: 942.47 | K11: 117.81 | L11: -117.81 | M11: -117.81 | N11: -117.81 | O11: -117.81 | P11: -117.81 | Q11: -117.81 | R11: -117.81 | S11: -117.8 | X11: {=SUMPRODUCT((LEFT($L$7:$W$7,3)<=$AA$2)*L11:W11)} -> -942.47 | Y11: =IF(Schedule3[[#This Row],[Prior Yr End Balance Forward]]<>"",Schedule3[[#This Row],[Prior Yr End Balance Forward]]+SUM(Schedule3[[#This Row],[P01.26]:[P12.26]]),Schedule3[[#This Row],[Amount Paid]]+SUM(Schedule3[[#This Row],[P01.26]:[P12.26]])) -> 0 | Z11: =IF(OR(B11<>B12,D11<>D12),SUMIFS(AA:AA,B:B,B11,D:D,D11),"") -> 0 | AA11: {=IF(Schedule3[[#This Row],[GL Acct]]=232000,Schedule3[[#This Row],[Prior Yr End Balance Forward]]+Schedule3[[#This Row],[YTD Amortization]],IF(OR(Schedule3[[#This Row],[Date ]]="", Schedule3[[#This Row],[Date ]]>EOMONTH(DATE(2026,VALUE(MID($AA$2,2,2)),1),0)), Schedule3[[#This Row],[P01.26]], IF(Schedule3[[#This Row],[Prior Yr End Balance Forward]]<>"", Schedule3[[#This Row],[Prior Yr End Balance Forward]], IF(Schedule3[[#This Row],[Amount Paid]]<>"",Schedule3[[#This Row],[Amount Paid]],0))+SUMPRODUCT((COLUMN(Schedule3[[#This Row],[P01.26]]:Schedule3[[#This Row],[P12.26]])<=COLUMN(INDIRECT("Schedule3[P"&MID($AA$2,2,2)&".26]")))*Schedule3[[#This Row],[P01.26]]:Schedule3[[#This Row],[P12.26]])))} -> 0
A12: Alameda County PPTaxes | B12: 5592 | C12: QCJ | D12: 138500 | F12: 708500 | G12: 45903 | H12: 09/01/25 - 08/31/26 | I12: 803.59 | J12: 535.73 | K12: 66.97 | L12: -66.97 | M12: -66.97 | N12: -66.97 | O12: -66.97 | P12: -66.97 | Q12: -66.97 | R12: -66.97 | S12: -66.94 | X12: {=SUMPRODUCT((LEFT($L$7:$W$7,3)<=$AA$2)*L12:W12)} -> -535.73 | Y12: =IF(Schedule3[[#This Row],[Prior Yr End Balance Forward]]<>"",Schedule3[[#This Row],[Prior Yr End Balance Forward]]+SUM(Schedule3[[#This Row],[P01.26]:[P12.26]]),Schedule3[[#This Row],[Amount Paid]]+SUM(Schedule3[[#This Row],[P01.26]:[P12.26]])) -> 0 | Z12: =IF(OR(B12<>B13,D12<>D13),SUMIFS(AA:AA,B:B,B12,D:D,D12),"") -> 0 | AA12: {=IF(Schedule3[[#This Row],[GL Acct]]=232000,Schedule3[[#This Row],[Prior Yr End Balance Forward]]+Schedule3[[#This Row],[YTD Amortization]],IF(OR(Schedule3[[#This Row],[Date ]]="", Schedule3[[#This Row],[Date ]]>EOMONTH(DATE(2026,VALUE(MID($AA$2,2,2)),1),0)), Schedule3[[#This Row],[P01.26]], IF(Schedule3[[#This Row],[Prior Yr End Balance Forward]]<>"", Schedule3[[#This Row],[Prior Yr End Balance Forward]], IF(Schedule3[[#This Row],[Amount Paid]]<>"",Schedule3[[#This Row],[Amount Paid]],0))+SUMPRODUCT((COLUMN(Schedule3[[#This Row],[P01.26]]:Schedule3[[#This Row],[P12.26]])<=COLUMN(INDIRECT("Schedule3[P"&MID($AA$2,2,2)&".26]")))*Schedule3[[#This Row],[P01.26]]:Schedule3[[#This Row],[P12.26]])))} -> 0
A13: Solano County PPTaxes | B13: 5813 | C13: QCJ | D13: 138500 | F13: 708500 | G13: 45903 | H13: 09/01/25 - 08/31/26 | I13: 1710.95 | J13: 1140.63 | K13: 142.58 | L13: -142.58 | M13: -142.58 | N13: -142.58 | O13: -142.58 | P13: -142.58 | Q13: -142.58 | R13: -142.58 | S13: -142.57 | X13: {=SUMPRODUCT((LEFT($L$7:$W$7,3)<=$AA$2)*L13:W13)} -> -1140.63 | Y13: =IF(Schedule3[[#This Row],[Prior Yr End Balance Forward]]<>"",Schedule3[[#This Row],[Prior Yr End Balance Forward]]+SUM(Schedule3[[#This Row],[P01.26]:[P12.26]]),Schedule3[[#This Row],[Amount Paid]]+SUM(Schedule3[[#This Row],[P01.26]:[P12.26]])) -> 0 | Z13: =IF(OR(B13<>B14,D13<>D14),SUMIFS(AA:AA,B:B,B13,D:D,D13),"") -> 0 | AA13: {=IF(Schedule3[[#This Row],[GL Acct]]=232000,Schedule3[[#This Row],[Prior Yr End Balance Forward]]+Schedule3[[#This Row],[YTD Amortization]],IF(OR(Schedule3[[#This Row],[Date ]]="", Schedule3[[#This Row],[Date ]]>EOMONTH(DATE(2026,VALUE(MID($AA$2,2,2)),1),0)), Schedule3[[#This Row],[P01.26]], IF(Schedule3[[#This Row],[Prior Yr End Balance Forward]]<>"", Schedule3[[#This Row],[Prior Yr End Balance Forward]], IF(Schedule3[[#This Row],[Amount Paid]]<>"",Schedule3[[#This Row],[Amount Paid]],0))+SUMPRODUCT((COLUMN(Schedule3[[#This Row],[P01.26]]:Schedule3[[#This Row],[P12.26]])<=COLUMN(INDIRECT("Schedule3[P"&MID($AA$2,2,2)&".26]")))*Schedule3[[#This Row],[P01.26]]:Schedule3[[#This Row],[P12.26]])))} -> 0
A14: Contra Costa County PPTaxes | B14: 8732 | C14: QCJ | D14: 138500 | F14: 708500 | G14: 45903 | H14: 09/01/25 - 08/31/26 | I14: 7824.23 | J14: 5216.15 | K14: 652.02 | L14: -652.02 | M14: -652.02 | N14: -652.02 | O14: -652.02 | P14: -652.02 | Q14: -652.02 | R14: -652.02 | S14: -652.01 | X14: {=SUMPRODUCT((LEFT($L$7:$W$7,3)<=$AA$2)*L14:W14)} -> -5216.15 | Y14: =IF(Schedule3[[#This Row],[Prior Yr End Balance Forward]]<>"",Schedule3[[#This Row],[Prior Yr End Balance Forward]]+SUM(Schedule3[[#This Row],[P01.26]:[P12.26]]),Schedule3[[#This Row],[Amount Paid]]+SUM(Schedule3[[#This Row],[P01.26]:[P12.26]])) -> 0 | Z14: =IF(OR(B14<>B15,D14<>D15),SUMIFS(AA:AA,B:B,B14,D:D,D14),"") -> 0 | AA14: {=IF(Schedule3[[#This Row],[GL Acct]]=232000,Schedule3[[#This Row],[Prior Yr End Balance Forward]]+Schedule3[[#This Row],[YTD Amortization]],IF(OR(Schedule3[[#This Row],[Date ]]="", Schedule3[[#This Row],[Date ]]>EOMONTH(DATE(2026,VALUE(MID($AA$2,2,2)),1),0)), Schedule3[[#This Row],[P01.26]], IF(Schedule3[[#This Row],[Prior Yr End Balance Forward]]<>"", Schedule3[[#This Row],[Prior Yr End Balance Forward]], IF(Schedule3[[#This Row],[Amount Paid]]<>"",Schedule3[[#This Row],[Amount Paid]],0))+SUMPRODUCT((COLUMN(Schedule3[[#This Row],[P01.26]]:Schedule3[[#This Row],[P12.26]])<=COLUMN(INDIRECT("Schedule3[P"&MID($AA$2,2,2)&".26]")))*Schedule3[[#This Row],[P01.26]]:Schedule3[[#This Row],[P12.26]])))} -> 0
A15: Solano County PPTaxes | B15: 8972 | C15: QCJ | D15: 138500 | F15: 708500 | G15: 45903 | H15: 09/01/25 - 08/31/26 | I15: 1069.59 | J15: 713.06 | K15: 89.13 | L15: -89.13 | M15: -89.13 | N15: -89.13 | O15: -89.13 | P15: -89.13 | Q15: -89.13 | R15: -89.13 | S15: -89.15 | X15: {=SUMPRODUCT((LEFT($L$7:$W$7,3)<=$AA$2)*L15:W15)} -> -713.06 | Y15: =IF(Schedule3[[#This Row],[Prior Yr End Balance Forward]]<>"",Schedule3[[#This Row],[Prior Yr End Balance Forward]]+SUM(Schedule3[[#This Row],[P01.26]:[P12.26]]),Schedule3[[#This Row],[Amount Paid]]+SUM(Schedule3[[#This Row],[P01.26]:[P12.26]])) -> 0 | Z15: =IF(OR(B15<>B16,D15<>D16),SUMIFS(AA:AA,B:B,B15,D:D,D15),"") -> 0 | AA15: {=IF(Schedule3[[#This Row],[GL Acct]]=232000,Schedule3[[#This Row],[Prior Yr End Balance Forward]]+Schedule3[[#This Row],[YTD Amortization]],IF(OR(Schedule3[[#This Row],[Date ]]="", Schedule3[[#This Row],[Date ]]>EOMONTH(DATE(2026,VALUE(MID($AA$2,2,2)),1),0)), Schedule3[[#This Row],[P01.26]], IF(Schedule3[[#This Row],[Prior Yr End Balance Forward]]<>"", Schedule3[[#This Row],[Prior Yr End Balance Forward]], IF(Schedule3[[#This Row],[Amount Paid]]<>"",Schedule3[[#This Row],[Amount Paid]],0))+SUMPRODUCT((COLUMN(Schedule3[[#This Row],[P01.26]]:Schedule3[[#This Row],[P12.26]])<=COLUMN(INDIRECT("Schedule3[P"&MID($AA$2,2,2)&".26]")))*Schedule3[[#This Row],[P01.26]]:Schedule3[[#This Row],[P12.26]])))} -> 0
A16: Sacramento County PPTaxes | B16: 10545 | C16: QCJ | D16: 138500 | F16: 708500 | G16: 45903 | H16: 09/01/25 - 08/31/26 | I16: 1772.58 | J16: 1181.72 | K16: 147.72 | L16: -147.72 | M16: -147.72 | N16: -147.72 | O16: -147.72 | P16: -147.72 | Q16: -147.72 | R16: -147.72 | S16: -147.68 | X16: {=SUMPRODUCT((LEFT($L$7:$W$7,3)<=$AA$2)*L16:W16)} -> -1181.72 | Y16: =IF(Schedule3[[#This Row],[Prior Yr End Balance Forward]]<>"",Schedule3[[#This Row],[Prior Yr End Balance Forward]]+SUM(Schedule3[[#This Row],[P01.26]:[P12.26]]),Schedule3[[#This Row],[Amount Paid]]+SUM(Schedule3[[#This Row],[P01.26]:[P12.26]])) -> 0 | Z16: =IF(OR(B16<>B17,D16<>D17),SUMIFS(AA:AA,B:B,B16,D:D,D16),"") -> 0 | AA16: {=IF(Schedule3[[#This Row],[GL Acct]]=232000,Schedule3[[#This Row],[Prior Yr End Balance Forward]]+Schedule3[[#This Row],[YTD Amortization]],IF(OR(Schedule3[[#This Row],[Date ]]="", Schedule3[[#This Row],[Date ]]>EOMONTH(DATE(2026,VALUE(MID($AA$2,2,2)),1),0)), Schedule3[[#This Row],[P01.26]], IF(Schedule3[[#This Row],[Prior Yr End Balance Forward]]<>"", Schedule3[[#This Row],[Prior Yr End Balance Forward]], IF(Schedule3[[#This Row],[Amount Paid]]<>"",Schedule3[[#This Row],[Amount Paid]],0))+SUMPRODUCT((COLUMN(Schedule3[[#This Row],[P01.26]]:Schedule3[[#This Row],[P12.26]])<=COLUMN(INDIRECT("Schedule3[P"&MID($AA$2,2,2)&".26]")))*Schedule3[[#This Row],[P01.26]]:Schedule3[[#This Row],[P12.26]])))} -> 0
A17: San Joaquin County PPTaxes | B17: 10752 | C17: QCJ | D17: 138500 | F17: 708500 | G17: 45903 | H17: 09/01/25 - 08/31/26 | I17: 2504.66 | J17: 1669.77 | K17: 208.72 | L17: -208.72 | M17: -208.72 | N17: -208.72 | O17: -208.72 | P17: -208.72 | Q17: -208.72 | R17: -208.72 | S17: -208.73 | X17: {=SUMPRODUCT((LEFT($L$7:$W$7,3)<=$AA$2)*L17:W17)} -> -1669.77 | Y17: =IF(Schedule3[[#This Row],[Prior Yr End Balance Forward]]<>"",Schedule3[[#This Row],[Prior Yr End Balance Forward]]+SUM(Schedule3[[#This Row],[P01.26]:[P12.26]]),Schedule3[[#This Row],[Amount Paid]]+SUM(Schedule3[[#This Row],[P01.26]:[P12.26]])) -> 0 | Z17: =IF(OR(B17<>B18,D17<>D18),SUMIFS(AA:AA,B:B,B17,D:D,D17),"") -> 0 | AA17: {=IF(Schedule3[[#This Row],[GL Acct]]=232000,Schedule3[[#This Row],[Prior Yr End Balance Forward]]+Schedule3[[#This Row],[YTD Amortization]],IF(OR(Schedule3[[#This Row],[Date ]]="", Schedule3[[#This Row],[Date ]]>EOMONTH(DATE(2026,VALUE(MID($AA$2,2,2)),1),0)), Schedule3[[#This Row],[P01.26]], IF(Schedule3[[#This Row],[Prior Yr End Balance Forward]]<>"", Schedule3[[#This Row],[Prior Yr End Balance Forward]], IF(Schedule3[[#This Row],[Amount Paid]]<>"",Schedule3[[#This Row],[Amount Paid]],0))+SUMPRODUCT((COLUMN(Schedule3[[#This Row],[P01.26]]:Schedule3[[#This Row],[P12.26]])<=COLUMN(INDIRECT("Schedule3[P"&MID($AA$2,2,2)&".26]")))*Schedule3[[#This Row],[P01.26]]:Schedule3[[#This Row],[P12.26]])))} -> 0
A18: Contra Costa County PPTaxes | B18: 10921 | C18: QCJ | D18: 138500 | F18: 708500 | G18: 45903 | H18: 09/01/25 - 08/31/26 | I18: 2878.37 | J18: 1918.91 | K18: 239.86 | L18: -239.86 | M18: -239.86 | N18: -239.86 | O18: -239.86 | P18: -239.86 | Q18: -239.86 | R18: -239.86 | S18: -239.89 | X18: {=SUMPRODUCT((LEFT($L$7:$W$7,3)<=$AA$2)*L18:W18)} -> -1918.91 | Y18: =IF(Schedule3[[#This Row],[Prior Yr End Balance Forward]]<>"",Schedule3[[#This Row],[Prior Yr End Balance Forward]]+SUM(Schedule3[[#This Row],[P01.26]:[P12.26]]),Schedule3[[#This Row],[Amount Paid]]+SUM(Schedule3[[#This Row],[P01.26]:[P12.26]])) -> -2.2737368e-13 | Z18: =IF(OR(B18<>B19,D18<>D19),SUMIFS(AA:AA,B:B,B18,D:D,D18),"") -> -2.2737368e-13 | AA18: {=IF(Schedule3[[#This Row],[GL Acct]]=232000,Schedule3[[#This Row],[Prior Yr End Balance Forward]]+Schedule3[[#This Row],[YTD Amortization]],IF(OR(Schedule3[[#This Row],[Date ]]="", Schedule3[[#This Row],[Date ]]>EOMONTH(DATE(2026,VALUE(MID($AA$2,2,2)),1),0)), Schedule3[[#This Row],[P01.26]], IF(Schedule3[[#This Row],[Prior Yr End Balance Forward]]<>"", Schedule3[[#This Row],[Prior Yr End Balance Forward]], IF(Schedule3[[#This Row],[Amount Paid]]<>"",Schedule3[[#This Row],[Amount Paid]],0))+SUMPRODUCT((COLUMN(Schedule3[[#This Row],[P01.26]]:Schedule3[[#This Row],[P12.26]])<=COLUMN(INDIRECT("Schedule3[P"&MID($AA$2,2,2)&".26]")))*Schedule3[[#This Row],[P01.26]]:Schedule3[[#This Row],[P12.26]])))} -> -2.2737368e-13
A19: Sacramento County PPTaxes | B19: 10989 | C19: QCJ | D19: 138500 | F19: 708500 | G19: 45903 | H19: 09/01/25 - 08/31/26 | I19: 1208.05 | J19: 805.37 | K19: 100.67 | L19: -100.67 | M19: -100.67 | N19: -100.67 | O19: -100.67 | P19: -100.67 | Q19: -100.67 | R19: -100.67 | S19: -100.68 | X19: {=SUMPRODUCT((LEFT($L$7:$W$7,3)<=$AA$2)*L19:W19)} -> -805.37 | Y19: =IF(Schedule3[[#This Row],[Prior Yr End Balance Forward]]<>"",Schedule3[[#This Row],[Prior Yr End Balance Forward]]+SUM(Schedule3[[#This Row],[P01.26]:[P12.26]]),Schedule3[[#This Row],[Amount Paid]]+SUM(Schedule3[[#This Row],[P01.26]:[P12.26]])) -> 0 | Z19: =IF(OR(B19<>B20,D19<>D20),SUMIFS(AA:AA,B:B,B19,D:D,D19),"") -> 0 | AA19: {=IF(Schedule3[[#This Row],[GL Acct]]=232000,Schedule3[[#This Row],[Prior Yr End Balance Forward]]+Schedule3[[#This Row],[YTD Amortization]],IF(OR(Schedule3[[#This Row],[Date ]]="", Schedule3[[#This Row],[Date ]]>EOMONTH(DATE(2026,VALUE(MID($AA$2,2,2)),1),0)), Schedule3[[#This Row],[P01.26]], IF(Schedule3[[#This Row],[Prior Yr End Balance Forward]]<>"", Schedule3[[#This Row],[Prior Yr End Balance Forward]], IF(Schedule3[[#This Row],[Amount Paid]]<>"",Schedule3[[#This Row],[Amount Paid]],0))+SUMPRODUCT((COLUMN(Schedule3[[#This Row],[P01.26]]:Schedule3[[#This Row],[P12.26]])<=COLUMN(INDIRECT("Schedule3[P"&MID($AA$2,2,2)&".26]")))*Schedule3[[#This Row],[P01.26]]:Schedule3[[#This Row],[P12.26]])))} -> 0
A20: Sacramento County PPTaxes | B20: 11218 | C20: QCJ | D20: 138500 | F20: 708500 | G20: 45903 | H20: 09/01/25 - 08/31/26 | I20: 1948.2 | J20: 1298.8 | K20: 162.35 | L20: -162.35 | M20: -162.35 | N20: -162.35 | O20: -162.35 | P20: -162.35 | Q20: -162.35 | R20: -162.35 | S20: -162.35 | X20: {=SUMPRODUCT((LEFT($L$7:$W$7,3)<=$AA$2)*L20:W20)} -> -1298.8 | Y20: =IF(Schedule3[[#This Row],[Prior Yr End Balance Forward]]<>"",Schedule3[[#This Row],[Prior Yr End Balance Forward]]+SUM(Schedule3[[#This Row],[P01.26]:[P12.26]]),Schedule3[[#This Row],[Amount Paid]]+SUM(Schedule3[[#This Row],[P01.26]:[P12.26]])) -> 0 | Z20: =IF(OR(B20<>B21,D20<>D21),SUMIFS(AA:AA,B:B,B20,D:D,D20),"") -> 0 | AA20: {=IF(Schedule3[[#This Row],[GL Acct]]=232000,Schedule3[[#This Row],[Prior Yr End Balance Forward]]+Schedule3[[#This Row],[YTD Amortization]],IF(OR(Schedule3[[#This Row],[Date ]]="", Schedule3[[#This Row],[Date ]]>EOMONTH(DATE(2026,VALUE(MID($AA$2,2,2)),1),0)), Schedule3[[#This Row],[P01.26]], IF(Schedule3[[#This Row],[Prior Yr End Balance Forward]]<>"", Schedule3[[#This Row],[Prior Yr End Balance Forward]], IF(Schedule3[[#This Row],[Amount Paid]]<>"",Schedule3[[#This Row],[Amount Paid]],0))+SUMPRODUCT((COLUMN(Schedule3[[#This Row],[P01.26]]:Schedule3[[#This Row],[P12.26]])<=COLUMN(INDIRECT("Schedule3[P"&MID($AA$2,2,2)&".26]")))*Schedule3[[#This Row],[P01.26]]:Schedule3[[#This Row],[P12.26]])))} -> 0
... A40: San Joaquin County PPTaxes | B40: 14869 | C40: QCJ | D40: 138500 | F40: 708500 | G40: 45903 | H40: 09/01/25 - 08/31/26 | I40: 2811.33 | J40: 1874.22 | K40: 234.28 | L40: -234.28 | M40: -234.28 | N40: -234.28 | O40: -234.28 | P40: -234.28 | Q40: -234.28 | R40: -234.28 | S40: -234.26 | X40: {=SUMPRODUCT((LEFT($L$7:$W$7,3)<=$AA$2)*L40:W40)} -> -1874.22 | Y40: =IF(Schedule3[[#This Row],[Prior Yr End Balance Forward]]<>"",Schedule3[[#This Row],[Prior Yr End Balance Forward]]+SUM(Schedule3[[#This Row],[P01.26]:[P12.26]]),Schedule3[[#This Row],[Amount Paid]]+SUM(Schedule3[[#This Row],[P01.26]:[P12.26]])) -> 0 | Z40: =IF(OR(B40<>B41,D40<>D41),SUMIFS(AA:AA,B:B,B40,D:D,D40),"") -> 0 | AA40: {=IF(Schedule3[[#This Row],[GL Acct]]=232000,Schedule3[[#This Row],[Prior Yr End Balance Forward]]+Schedule3[[#This Row],[YTD Amortization]],IF(OR(Schedule3[[#This Row],[Date ]]="", Schedule3[[#This Row],[Date ]]>EOMONTH(DATE(2026,VALUE(MID($AA$2,2,2)),1),0)), Schedule3[[#This Row],[P01.26]], IF(Schedule3[[#This Row],[Prior Yr End Balance Forward]]<>"", Schedule3[[#This Row],[Prior Yr End Balance Forward]], IF(Schedule3[[#This Row],[Amount Paid]]<>"",Schedule3[[#This Row],[Amount Paid]],0))+SUMPRODUCT((COLUMN(Schedule3[[#This Row],[P01.26]]:Schedule3[[#This Row],[P12.26]])<=COLUMN(INDIRECT("Schedule3[P"&MID($AA$2,2,2)&".26]")))*Schedule3[[#This Row],[P01.26]]:Schedule3[[#This Row],[P12.26]])))} -> 0
A41: Contra Costa County PPTaxes | B41: 12114 | C41: QMSI | D41: 138500 | F41: 708500 | G41: 45903 | H41: 09/01/25 - 08/31/26 | I41: 940.7 | J41: 627.14 | K41: =ROUND(IFERROR(I41/12,0),2) -> 78.39 | L41: -78.39 | M41: -78.39 | N41: -78.39 | O41: -78.39 | P41: -78.39 | Q41: -78.39 | R41: -78.39 | S41: -78.41 | X41: {=SUMPRODUCT((LEFT($L$7:$W$7,3)<=$AA$2)*L41:W41)} -> -627.14 | Y41: =IF(Schedule3[[#This Row],[Prior Yr End Balance Forward]]<>"",Schedule3[[#This Row],[Prior Yr End Balance Forward]]+SUM(Schedule3[[#This Row],[P01.26]:[P12.26]]),Schedule3[[#This Row],[Amount Paid]]+SUM(Schedule3[[#This Row],[P01.26]:[P12.26]])) -> 0 | Z41: =IF(OR(B41<>B42,D41<>D42),SUMIFS(AA:AA,B:B,B41,D:D,D41),"") -> 0 | AA41: {=IF(Schedule3[[#This Row],[GL Acct]]=232000,Schedule3[[#This Row],[Prior Yr End Balance Forward]]+Schedule3[[#This Row],[YTD Amortization]],IF(OR(Schedule3[[#This Row],[Date ]]="", Schedule3[[#This Row],[Date ]]>EOMONTH(DATE(2026,VALUE(MID($AA$2,2,2)),1),0)), Schedule3[[#This Row],[P01.26]], IF(Schedule3[[#This Row],[Prior Yr End Balance Forward]]<>"", Schedule3[[#This Row],[Prior Yr End Balance Forward]], IF(Schedule3[[#This Row],[Amount Paid]]<>"",Schedule3[[#This Row],[Amount Paid]],0))+SUMPRODUCT((COLUMN(Schedule3[[#This Row],[P01.26]]:Schedule3[[#This Row],[P12.26]])<=COLUMN(INDIRECT("Schedule3[P"&MID($AA$2,2,2)&".26]")))*Schedule3[[#This Row],[P01.26]]:Schedule3[[#This Row],[P12.26]])))} -> 0
A42: Sutter Couty Treasurer PPTaxes | B42: 11422 | C42: QMSI | D42: 138500 | F42: 708500 | G42: 45903 | H42: 09/01/25 - 08/31/26 | I42: 2150.62 | J42: 1433.75 | L42: -1433.75 | S42: 0 | X42: {=SUMPRODUCT((LEFT($L$7:$W$7,3)<=$AA$2)*L42:W42)} -> -1433.75 | Y42: =IF(Schedule3[[#This Row],[Prior Yr End Balance Forward]]<>"",Schedule3[[#This Row],[Prior Yr End Balance Forward]]+SUM(Schedule3[[#This Row],[P01.26]:[P12.26]]),Schedule3[[#This Row],[Amount Paid]]+SUM(Schedule3[[#This Row],[P01.26]:[P12.26]])) -> 0 | Z42: =IF(OR(B42<>B43,D42<>D43),SUMIFS(AA:AA,B:B,B42,D:D,D42),"") -> 0 | AA42: {=IF(Schedule3[[#This Row],[GL Acct]]=232000,Schedule3[[#This Row],[Prior Yr End Balance Forward]]+Schedule3[[#This Row],[YTD Amortization]],IF(OR(Schedule3[[#This Row],[Date ]]="", Schedule3[[#This Row],[Date ]]>EOMONTH(DATE(2026,VALUE(MID($AA$2,2,2)),1),0)), Schedule3[[#This Row],[P01.26]], IF(Schedule3[[#This Row],[Prior Yr End Balance Forward]]<>"", Schedule3[[#This Row],[Prior Yr End Balance Forward]], IF(Schedule3[[#This Row],[Amount Paid]]<>"",Schedule3[[#This Row],[Amount Paid]],0))+SUMPRODUCT((COLUMN(Schedule3[[#This Row],[P01.26]]:Schedule3[[#This Row],[P12.26]])<=COLUMN(INDIRECT("Schedule3[P"&MID($AA$2,2,2)&".26]")))*Schedule3[[#This Row],[P01.26]]:Schedule3[[#This Row],[P12.26]])))} -> 0
I43: =SUBTOTAL(109,Schedule3[Amount Paid]) -> 115144.05 | J43: =SUBTOTAL(109,Schedule3[Prior Yr End Balance Forward]) -> 76762.68 | K43: =SUM(K9:K41) -> 9416.1 | L43: =SUBTOTAL(109,Schedule3[P01.26]) -> -10849.85 | M43: =SUBTOTAL(109,Schedule3[P02.26]) -> -9416.1 | N43: =SUBTOTAL(109,Schedule3[P03.26]) -> -9416.1 | O43: =SUBTOTAL(109,Schedule3[P04.26]) -> -9416.1 | P43: =SUBTOTAL(109,Schedule3[P05.26]) -> -9416.1 | Q43: =SUBTOTAL(109,Schedule3[P06.26]) -> -9416.1 | R43: =SUBTOTAL(109,Schedule3[P07.26]) -> -9416.1 | S43: =SUBTOTAL(109,Schedule3[P08.26]) -> -9416.23 | T43: =SUBTOTAL(109,Schedule3[P09.26]) -> 0 | U43: =SUBTOTAL(109,Schedule3[P10.26]) -> 0 | V43: =SUBTOTAL(109,Schedule3[P11.26]) -> 0 | W43: =SUBTOTAL(109,Schedule3[P12.26]) -> 0 | X43: =SUBTOTAL(109,Schedule3[YTD Amortization]) -> -76762.68 | Y43: =SUBTOTAL(109,Schedule3[Ending Prepaid Balance]) -> 1.1368684e-12 | Z43: =SUBTOTAL(109,Schedule3[ENDING BAL PER STORE]) -> 1.1368684e-12 | AA43: =SUBTOTAL(109,Schedule3[Balance as of Period]) -> 1.1368684e-12
H44: =SUM(I9:I42) -> 115144.05
A45: "LAST UPDATED: "&TEXT(NOW(),"mm/dd/yyyy hh:mm:ss AM/PM") | K45: ="138500 GL BAL "&TEXT(EOMONTH(DATE(2026,VALUE(MID($AA$2,2,2)),1),0),"MM/DD/YYYY") -> 138500 GL BAL 08/31/YYYY | L45: 65912.83 | M45: 56496.73 | N45: 47080.63 | O45: 37664.53 | P45: 28248.43 | Q45: 18832.33
A46: Notes: | K46: Dif | L46: =IF(LEFT(L$7,3)=$AA$2,SUMIF(Schedule3[GL Acct],138500,Schedule3[Balance as of Period])- L45,IF( LEFT(L$7,3)>$AA$2,"<", IF(LEFT(L$7,3)<$AA$2,">",0))) -> > | M46: =IF(LEFT(M$7,3)=$AA$2,SUMIF(Schedule3[GL Acct],138500,Schedule3[Balance as of Period])- M45,IF( LEFT(M$7,3)>$AA$2,"<", IF(LEFT(M$7,3)<$AA$2,">",0))) -> > | N46: =IF(LEFT(N$7,3)=$AA$2,SUMIF(Schedule3[GL Acct],138500,Schedule3[Balance as of Period])- N45,IF( LEFT(N$7,3)>$AA$2,"<", IF(LEFT(N$7,3)<$AA$2,">",0))) -> > | O46: =IF(LEFT(O$7,3)=$AA$2,SUMIF(Schedule3[GL Acct],138500,Schedule3[Balance as of Period])- O45,IF( LEFT(O$7,3)>$AA$2,"<", IF(LEFT(O$7,3)<$AA$2,">",0))) -> > | P46: =IF(LEFT(P$7,3)=$AA$2,SUMIF(Schedule3[GL Acct],138500,Schedule3[Balance as of Period])- P45,IF( LEFT(P$7,3)>$AA$2,"<", IF(LEFT(P$7,3)<$AA$2,">",0))) -> > | Q46: =IF(LEFT(Q$7,3)=$AA$2,SUMIF(Schedule3[GL Acct],138500,Schedule3[Balance as of Period])- Q45,IF( LEFT(Q$7,3)>$AA$2,"<", IF(LEFT(Q$7,3)<$AA$2,">",0))) -> > | R46: =IF(LEFT(R$7,3)=$AA$2,SUMIF(Schedule3[GL Acct],138500,Schedule3[Balance as of Period])- R45,IF( LEFT(R$7,3)>$AA$2,"<", IF(LEFT(R$7,3)<$AA$2,">",0))) -> > | S46: =IF(LEFT(S$7,3)=$AA$2,SUMIF(Schedule3[GL Acct],138500,Schedule3[Balance as of Period])- S45,IF( LEFT(S$7,3)>$AA$2,"<", IF(LEFT(S$7,3)<$AA$2,">",0))) -> 1.1368684e-12 | ... W46: =IF(LEFT(W$7,3)=$AA$2,SUMIF(Schedule3[GL Acct],138500,Schedule3[Balance as of Period])- W45,IF( LEFT(W$7,3)>$AA$2,"<", IF(LEFT(W$7,3)<$AA$2,">",0))) -> <
A48: LAST UPDATED: 07/02/2026 07:19:04 AM
A50: Make sure to manually upload last amort. to Adjust cents, leaving Y column on 0.

Sheet Dim Bal 138500
A1: Company Name: | B1: Quikserve Cajun - Popeyes
A2: Report Name: | B2: Dimension balances report
A3: Start Date: | B3: 04/01/2026
A4: End Date: | B4: 04/30/2026
A5: Location | B5: Opening balance (USD) | C5: Period balance(USD) | D5: Closing balance (USD) | E5: Schedule | F5: Dif
A6: 2902 | B6: 1985.77 | C6: -397.15 | D6: 1588.62 | E6: =SUMIFS('Schedule 2026'!AA:AA,'Schedule 2026'!B:B,'Dim Bal 138500'!A6) -> 0 | F6: =D6-E6 -> 1588.62
A7: 4579 | B7: 2486.08 | C7: -497.21 | D7: 1988.87 | E7: =SUMIFS('Schedule 2026'!AA:AA,'Schedule 2026'!B:B,'Dim Bal 138500'!A7) -> 0 | F7: =D7-E7 -> 1988.87
A8: 5328 | B8: 589.04 | C8: -117.81 | D8: 471.23 | E8: =SUMIFS('Schedule 2026'!AA:AA,'Schedule 2026'!B:B,'Dim Bal 138500'!A8) -> 0 | F8: =D8-E8 -> 471.23
A9: 5592 | B9: 334.82 | C9: -66.97 | D9: 267.85 | E9: =SUMIFS('Schedule 2026'!AA:AA,'Schedule 2026'!B:B,'Dim Bal 138500'!A9) -> 0 | F9: =D9-E9 -> 267.85
A10: 5813 | B10: 712.89 | C10: -142.58 | D10: 570.31 | E10: =SUMIFS('Schedule 2026'!AA:AA,'Schedule 2026'!B:B,'Dim Bal 138500'!A10) -> 0 | F10: =D10-E10 -> 570.31
A11: 8732 | B11: 3260.09 | C11: -652.02 | D11: 2608.07 | E11: =SUMIFS('Schedule 2026'!AA:AA,'Schedule 2026'!B:B,'Dim Bal 138500'!A11) -> 0 | F11: =D11-E11 -> 2608.07
A12: 8972 | B12: 445.67 | C12: -89.13 | D12: 356.54 | E12: =SUMIFS('Schedule 2026'!AA:AA,'Schedule 2026'!B:B,'Dim Bal 138500'!A12) -> 0 | F12: =D12-E12 -> 356.54
A13: 10545 | B13: 738.56 | C13: -147.72 | D13: 590.84 | E13: =SUMIFS('Schedule 2026'!AA:AA,'Schedule 2026'!B:B,'Dim Bal 138500'!A13) -> 0 | F13: =D13-E13 -> 590.84
A14: 10752 | B14: 1043.61 | C14: -208.72 | D14: 834.89 | E14: =SUMIFS('Schedule 2026'!AA:AA,'Schedule 2026'!B:B,'Dim Bal 138500'!A14) -> 0 | F14: =D14-E14 -> 834.89
A15: 10921 | B15: 1199.33 | C15: -239.86 | D15: 959.47 | E15: =SUMIFS('Schedule 2026'!AA:AA,'Schedule 2026'!B:B,'Dim Bal 138500'!A15) -> -2.2737368e-13 | F15: =D15-E15 -> 959.47
A16: 10989 | B16: 503.36 | C16: -100.67 | D16: 402.69 | E16: =SUMIFS('Schedule 2026'!AA:AA,'Schedule 2026'!B:B,'Dim Bal 138500'!A16) -> 0 | F16: =D16-E16 -> 402.69
A17: 11218 | B17: 811.75 | C17: -162.35 | D17: 649.4 | E17: =SUMIFS('Schedule 2026'!AA:AA,'Schedule 2026'!B:B,'Dim Bal 138500'!A17) -> 0 | F17: =D17-E17 -> 649.4
... A38: 14869 | B38: 1171.38 | C38: -234.28 | D38: 937.1 | E38: =SUMIFS('Schedule 2026'!AA:AA,'Schedule 2026'!B:B,'Dim Bal 138500'!A38) -> 0 | F38: =D38-E38 -> 937.1
A39: Grand total | B39: 47080.63 | C39: -9416.1 | D39: =SUM(D6:D38) -> 37664.53 | E39: =SUM(E6:E38) -> 1.1368684e-12 | F39: =SUM(F6:F38) -> 37664.53

Sheet Sheet3
A1: Location | B1: Posted dt. | C1: Doc dt. | D1: Doc | E1: Memo/Description | F1: Department | G1: Location | H1: Txn No | I1: JNL | J1: Debit | K1: Credit | L1: Balance | N1: Row Labels | O1: Sum of Balance
A2: 138000 - PREPAID PROPERTY TAX (Balance forward As of 04/01/2026) | L2: 103703.5 | N2: 2902 | O2: 21202.3 | P2: =SUMIF('Schedule 2026'!B:B,N2,'Schedule 2026'!#REF!) -> #REF!
A3: Quikserve Cajun, Inc | I3: B/F | L3: 85169.41 | N3: 4579 | O3: 7360.6 | P3: =SUMIF('Schedule 2026'!B:B,N3,'Schedule 2026'!#REF!) -> #REF!
A4: Quikserve Cajun, Inc : 2902 - Sacramento | I4: B/F | L4: 6057.79 | N4: 5328 | O4: 7431.53 | P4: =SUMIF('Schedule 2026'!B:B,N4,'Schedule 2026'!#REF!) -> #REF!
B5: 46113 | C5: 46113 | D5: 2902 CA SUPP RE PTAX 2025-26 / 2ND INS | E5: Bill - Sacramento County Unsecured Tax Unit: 2902 CA SUPPLEMENTAL PPD REAL_SECURED PROPERTY TAX 2025-26 / 2ND INS PAID (Jun-Nov Amort) | G5: 2902 | H5: 2189 | I5: APJ | J5: 4395.6 | L5: 10453.39 | N5: 5592 | O5: 16671.93 | P5: =SUMIF('Schedule 2026'!B:B,N5,'Schedule 2026'!#REF!) -> #REF!
B6: 46113 | C6: 46113 | D6: 2902 CA RE PTAX 2025-26 / 2ND INS | E6: Bill - Sacramento County Unsecured Tax Unit: 2902 CA PPD REAL_SECURED PROPERTY TAX 2025-26 / 2ND INS PAID (Jun-Nov Amort) | G6: 2902 | H6: 2189 | I6: APJ | J6: 13777.82 | L6: 24231.21 | N6: 5813 | O6: 6016.67 | P6: =SUMIF('Schedule 2026'!B:B,N6,'Schedule 2026'!#REF!) -> #REF!
B7: 46142 | C7: 46142 | E7: PLK PREPAID REAL PROPERTY TAX (DEC 2025 - MAY 2026) AMORT - 5/6 | G7: 2902 | H7: 11760 | I7: GJ | K7: 3028.91 | L7: 21202.3 | N7: 8593 | O7: 16474.17 | P7: =SUMIF('Schedule 2026'!B:B,N7,'Schedule 2026'!#REF!) -> #REF!
A8: Totals for Quikserve Cajun, Inc : 2902 - Sacramento | F8: {=IF(ISNUMBER(SEARCH("Totals",A8)),VALUE(_xlfn.TEXTJOIN("",TRUE,IF(ISNUMBER(--MID(A8,_xlfn.SEQUENCE(LEN(A8)),1)),MID(A8,_xlfn.SEQUENCE(LEN(A8)),1),""))),"")} -> 2902 | J8: 18173.42 | K8: 3028.91 | L8: 21202.3 | N8: 8732 | O8: 21084.21 | P8: =SUMIF('Schedule 2026'!B:B,N8,'Schedule 2026'!#REF!) -> #REF!
F9: {=IF(ISNUMBER(SEARCH("Totals",A9)),VALUE(_xlfn.TEXTJOIN("",TRUE,IF(ISNUMBER(--MID(A9,_xlfn.SEQUENCE(LEN(A9)),1)),MID(A9,_xlfn.SEQUENCE(LEN(A9)),1),""))),"")} | N9: 8972 | O9: 17571.58 | P9: =SUMIF('Schedule 2026'!B:B,N9,'Schedule 2026'!#REF!) -> #REF!
A10: Quikserve Cajun, Inc : 4579 - Sacramento | F10: {=IF(ISNUMBER(SEARCH("Totals",A10)),VALUE(_xlfn.TEXTJOIN("",TRUE,IF(ISNUMBER(--MID(A10,_xlfn.SEQUENCE(LEN(A10)),1)),MID(A10,_xlfn.SEQUENCE(LEN(A10)),1),""))),"")} | I10: B/F | L10: 2103.02 | N10: 10545 | O10: 9376.48 | P10: =SUMIF('Schedule 2026'!B:B,N10,'Schedule 2026'!#REF!) -> #REF!
B11: 46113 | C11: 46113 | D11: 4579 CA RE PTAX 2025-26 / 2ND INS | E11: Bill - Sacramento County Unsecured Tax Unit: 4579 CA PPD REAL_SECURED PROPERTY TAX 2025-26 / 2ND INS PAID (Jun-Nov Amort) | F11: {=IF(ISNUMBER(SEARCH("Totals",A11)),VALUE(_xlfn.TEXTJOIN("",TRUE,IF(ISNUMBER(--MID(A11,_xlfn.SEQUENCE(LEN(A11)),1)),MID(A11,_xlfn.SEQUENCE(LEN(A11)),1),""))),"")} | G11: 4579 | H11: 2189 | I11: APJ | J11: 6309.1 | L11: 8412.12 | N11: 10752 | O11: 7282.29 | P11: =SUMIF('Schedule 2026'!B:B,N11,'Schedule 2026'!#REF!) -> #REF!
B12: 46142 | C12: 46142 | E12: PLK PREPAID REAL PROPERTY TAX (DEC 2025 - MAY 2026) AMORT - 5/6 | F12: {=IF(ISNUMBER(SEARCH("Totals",A12)),VALUE(_xlfn.TEXTJOIN("",TRUE,IF(ISNUMBER(--MID(A12,_xlfn.SEQUENCE(LEN(A12)),1)),MID(A12,_xlfn.SEQUENCE(LEN(A12)),1),""))),"")} | G12: 4579 | H12: 11760 | I12: GJ | K12: 1051.52 | L12: 7360.6 | N12: 11218 | O12: 6712.98 | P12: =SUMIF('Schedule 2026'!B:B,N12,'Schedule 2026'!#REF!) -> #REF!
A13: Totals for Quikserve Cajun, Inc : 4579 - Sacramento | F13: {=IF(ISNUMBER(SEARCH("Totals",A13)),VALUE(_xlfn.TEXTJOIN("",TRUE,IF(ISNUMBER(--MID(A13,_xlfn.SEQUENCE(LEN(A13)),1)),MID(A13,_xlfn.SEQUENCE(LEN(A13)),1),""))),"")} -> 4579 | J13: 6309.1 | K13: 1051.52 | L13: 7360.6 | N13: 11422 | O13: 5625.38 | P13: =SUMIF('Schedule 2026'!B:B,N13,'Schedule 2026'!#REF!) -> #REF!
F14: {=IF(ISNUMBER(SEARCH("Totals",A14)),VALUE(_xlfn.TEXTJOIN("",TRUE,IF(ISNUMBER(--MID(A14,_xlfn.SEQUENCE(LEN(A14)),1)),MID(A14,_xlfn.SEQUENCE(LEN(A14)),1),""))),"")} | N14: 11423 | O14: 1241.17 | P14: =SUMIF('Schedule 2026'!B:B,N14,'Schedule 2026'!#REF!) -> #REF!
A15: Quikserve Cajun, Inc : 5328 - Oakland | F15: {=IF(ISNUMBER(SEARCH("Totals",A15)),VALUE(_xlfn.TEXTJOIN("",TRUE,IF(ISNUMBER(--MID(A15,_xlfn.SEQUENCE(LEN(A15)),1)),MID(A15,_xlfn.SEQUENCE(LEN(A15)),1),""))),"")} | I15: B/F | L15: 2123.29 | N15: 11424 | O15: 945.15 | P15: =SUMIF('Schedule 2026'!B:B,N15,'Schedule 2026'!#REF!) -> #REF!
B16: 46113 | C16: 46113 | D16: 5328 CA RE PTAX 2025-26 / 2ND INS | E16: Bill - Alameda County Treasurer Tax Collector: 5328 CA PPD REAL_SECURED PROPERTY TAX 2025-26 / 2ND INS PAID (Jun-Nov Amort) | F16: {=IF(ISNUMBER(SEARCH("Totals",A16)),VALUE(_xlfn.TEXTJOIN("",TRUE,IF(ISNUMBER(--MID(A16,_xlfn.SEQUENCE(LEN(A16)),1)),MID(A16,_xlfn.SEQUENCE(LEN(A16)),1),""))),"")} | G16: 5328 | H16: 2189 | I16: APJ | J16: 6369.89 | L16: 8493.18 | N16: 11425 | O16: 1097.96 | P16: =SUMIF('Schedule 2026'!B:B,N16,'Schedule 2026'!#REF!) -> #REF!
B17: 46142 | C17: 46142 | E17: PLK PREPAID REAL PROPERTY TAX (DEC 2025 - MAY 2026) AMORT - 5/6 | F17: {=IF(ISNUMBER(SEARCH("Totals",A17)),VALUE(_xlfn.TEXTJOIN("",TRUE,IF(ISNUMBER(--MID(A17,_xlfn.SEQUENCE(LEN(A17)),1)),MID(A17,_xlfn.SEQUENCE(LEN(A17)),1),""))),"")} | G17: 5328 | H17: 11760 | I17: GJ | K17: 1061.65 | L17: 7431.53 | N17: 11540 | O17: 8701.37 | P17: =SUMIF('Schedule 2026'!B:B,N17,'Schedule 2026'!#REF!) -> #REF!
A18: Totals for Quikserve Cajun, Inc : 5328 - Oakland | F18: {=IF(ISNUMBER(SEARCH("Totals",A18)),VALUE(_xlfn.TEXTJOIN("",TRUE,IF(ISNUMBER(--MID(A18,_xlfn.SEQUENCE(LEN(A18)),1)),MID(A18,_xlfn.SEQUENCE(LEN(A18)),1),""))),"")} -> 5328 | J18: 6369.89 | K18: 1061.65 | L18: 7431.53 | N18: 11580 | O18: 14249.73 | P18: =SUMIF('Schedule 2026'!B:B,N18,'Schedule 2026'!#REF!) -> #REF!
F19: {=IF(ISNUMBER(SEARCH("Totals",A19)),VALUE(_xlfn.TEXTJOIN("",TRUE,IF(ISNUMBER(--MID(A19,_xlfn.SEQUENCE(LEN(A19)),1)),MID(A19,_xlfn.SEQUENCE(LEN(A19)),1),""))),"")} | N19: 11691 | O19: 14259.36 | P19: =SUMIF('Schedule 2026'!B:B,N19,'Schedule 2026'!#REF!) -> #REF!
A20: Quikserve Cajun, Inc : 5592 - Newark | F20: {=IF(ISNUMBER(SEARCH("Totals",A20)),VALUE(_xlfn.TEXTJOIN("",TRUE,IF(ISNUMBER(--MID(A20,_xlfn.SEQUENCE(LEN(A20)),1)),MID(A20,_xlfn.SEQUENCE(LEN(A20)),1),""))),"")} | I20: B/F | L20: 4763.4 | N20: 11833 | O20: 9299.26 | P20: =SUMIF('Schedule 2026'!B:B,N20,'Schedule 2026'!#REF!) -> #REF!
B21: 46113 | C21: 46113 | D21: 5592 CA RE PTAX 2025-26 / 2ND INS | E21: Bill - Alameda County Treasurer Tax Collector: 5592 CA PPD REAL_SECURED PROPERTY TAX 2025-26 / 2ND INS PAID (Jun-Nov Amort) | F21: {=IF(ISNUMBER(SEARCH("Totals",A21)),VALUE(_xlfn.TEXTJOIN("",TRUE,IF(ISNUMBER(--MID(A21,_xlfn.SEQUENCE(LEN(A21)),1)),MID(A21,_xlfn.SEQUENCE(LEN(A21)),1),""))),"")} | G21: 5592 | H21: 2189 | I21: APJ | J21: 14290.24 | L21: 19053.64 | N21: 11922 | O21: 16902.1 | P21: =SUMIF('Schedule 2026'!B:B,N21,'Schedule 2026'!#REF!) -> #REF!
B22: 46142 | C22: 46142 | E22: PLK PREPAID REAL PROPERTY TAX (DEC 2025 - MAY 2026) AMORT - 5/6 | F22: {=IF(ISNUMBER(SEARCH("Totals",A22)),VALUE(_xlfn.TEXTJOIN("",TRUE,IF(ISNUMBER(--MID(A22,_xlfn.SEQUENCE(LEN(A22)),1)),MID(A22,_xlfn.SEQUENCE(LEN(A22)),1),""))),"")} | G22: 5592 | H22: 11760 | I22: GJ | K22: 2381.71 | L22: 16671.93 | N22: 12114 | O22: 28806.54 | P22: =SUMIF('Schedule 2026'!B:B,N22,'Schedule 2026'!#REF!) -> #REF!
A23: Totals for Quikserve Cajun, Inc : 5592 - Newark | F23: {=IF(ISNUMBER(SEARCH("Totals",A23)),VALUE(_xlfn.TEXTJOIN("",TRUE,IF(ISNUMBER(--MID(A23,_xlfn.SEQUENCE(LEN(A23)),1)),MID(A23,_xlfn.SEQUENCE(LEN(A23)),1),""))),"")} -> 5592 | J23: 14290.24 | K23: 2381.71 | L23: 16671.93 | N23: 12967 | O23: 12520.04 | P23: =SUMIF('Schedule 2026'!B:B,N23,'Schedule 2026'!#REF!) -> #REF!
F24: {=IF(ISNUMBER(SEARCH("Totals",A24)),VALUE(_xlfn.TEXTJOIN("",TRUE,IF(ISNUMBER(--MID(A24,_xlfn.SEQUENCE(LEN(A24)),1)),MID(A24,_xlfn.SEQUENCE(LEN(A24)),1),""))),"")} | N24: 13691 | O24: 3107.56 | P24: =SUMIF('Schedule 2026'!B:B,N24,'Schedule 2026'!#REF!) -> #REF!
A25: Quikserve Cajun, Inc : 5813 - Suisun City | F25: {=IF(ISNUMBER(SEARCH("Totals",A25)),VALUE(_xlfn.TEXTJOIN("",TRUE,IF(ISNUMBER(--MID(A25,_xlfn.SEQUENCE(LEN(A25)),1)),MID(A25,_xlfn.SEQUENCE(LEN(A25)),1),""))),"")} | I25: B/F | L25: 1719.2 | N25: 13903 | O25: 2279.07 | P25: =SUMIF('Schedule 2026'!B:B,N25,'Schedule 2026'!#REF!) -> #REF!
B26: 46113 | C26: 46113 | D26: 5813 CA RE PTAX 2025-26 / 2ND INS | E26: Bill - Solano County Treasury: 5813 CA PPD REAL_SECURED PROPERTY TAX 2025-26 / 2ND INS PAID (Jun-Nov Amort) | F26: {=IF(ISNUMBER(SEARCH("Totals",A26)),VALUE(_xlfn.TEXTJOIN("",TRUE,IF(ISNUMBER(--MID(A26,_xlfn.SEQUENCE(LEN(A26)),1)),MID(A26,_xlfn.SEQUENCE(LEN(A26)),1),""))),"")} | G26: 5813 | H26: 2189 | I26: APJ | J26: 5157.06 | L26: 6876.26 | N26: 13959 | O26: 6813.34 | P26: =SUMIF('Schedule 2026'!B:B,N26,'Schedule 2026'!#REF!) -> #REF!
B27: 46142 | C27: 46142 | E27: PLK PREPAID REAL PROPERTY TAX (DEC 2025 - MAY 2026) AMORT - 5/6 | F27: {=IF(ISNUMBER(SEARCH("Totals",A27)),VALUE(_xlfn.TEXTJOIN("",TRUE,IF(ISNUMBER(--MID(A27,_xlfn.SEQUENCE(LEN(A27)),1)),MID(A27,_xlfn.SEQUENCE(LEN(A27)),1),""))),"")} | G27: 5813 | H27: 11760 | I27: GJ | K27: 859.59 | L27: 6016.67 | N27: 14183 | O27: 10145.62 | P27: =SUMIF('Schedule 2026'!B:B,N27,'Schedule 2026'!#REF!) -> #REF!
A28: Totals for Quikserve Cajun, Inc : 5813 - Suisun City | F28: {=IF(ISNUMBER(SEARCH("Totals",A28)),VALUE(_xlfn.TEXTJOIN("",TRUE,IF(ISNUMBER(--MID(A28,_xlfn.SEQUENCE(LEN(A28)),1)),MID(A28,_xlfn.SEQUENCE(LEN(A28)),1),""))),"")} -> 5813 | J28: 5157.06 | K28: 859.59 | L28: 6016.67 | N28: 14210 | O28: 8289.78 | P28: =SUMIF('Schedule 2026'!B:B,N28,'Schedule 2026'!#REF!) -> #REF!
F29: {=IF(ISNUMBER(SEARCH("Totals",A29)),VALUE(_xlfn.TEXTJOIN("",TRUE,IF(ISNUMBER(--MID(A29,_xlfn.SEQUENCE(LEN(A29)),1)),MID(A29,_xlfn.SEQUENCE(LEN(A29)),1),""))),"")} | N29: 14589 | O29: 16377.61 | P29: =SUMIF('Schedule 2026'!B:B,N29,'Schedule 2026'!#REF!) -> #REF!
A30: Quikserve Cajun, Inc : 8732 - PITTSBURG | F30: {=IF(ISNUMBER(SEARCH("Totals",A30)),VALUE(_xlfn.TEXTJOIN("",TRUE,IF(ISNUMBER(--MID(A30,_xlfn.SEQUENCE(LEN(A30)),1)),MID(A30,_xlfn.SEQUENCE(LEN(A30)),1),""))),"")} | I30: B/F | L30: 6024.06 | N30: 14719 | O30: 15038.78 | P30: =SUMIF('Schedule 2026'!B:B,N30,'Schedule 2026'!#REF!) -> #REF!
B31: 46113 | C31: 46113 | D31: 8732 CA RE PTAX 2025-26 / 2ND INS | E31: Bill - Contra Costa County Tax Collector: 8732 CA PPD REAL_SECURED PROPERTY TAX 2025-26 / 2ND INS PAID (Jun-Nov Amort) | F31: {=IF(ISNUMBER(SEARCH("Totals",A31)),VALUE(_xlfn.TEXTJOIN("",TRUE,IF(ISNUMBER(--MID(A31,_xlfn.SEQUENCE(LEN(A31)),1)),MID(A31,_xlfn.SEQUENCE(LEN(A31)),1),""))),"")} | G31: 8732 | H31: 2189 | I31: APJ | J31: 18072.18 | L31: 24096.24 | O31: 721191
B32: 46142 | C32: 46142 | E32: PLK PREPAID REAL PROPERTY TAX (DEC 2025 - MAY 2026) AMORT - 5/6 | F32: {=IF(ISNUMBER(SEARCH("Totals",A32)),VALUE(_xlfn.TEXTJOIN("",TRUE,IF(ISNUMBER(--MID(A32,_xlfn.SEQUENCE(LEN(A32)),1)),MID(A32,_xlfn.SEQUENCE(LEN(A32)),1),""))),"")} | G32: 8732 | H32: 11760 | I32: GJ | K32: 3012.03 | L32: 21084.21 | N32: #VALUE! | O32: 276113.51
A33: Totals for Quikserve Cajun, Inc : 8732 - PITTSBURG | F33: {=IF(ISNUMBER(SEARCH("Totals",A33)),VALUE(_xlfn.TEXTJOIN("",TRUE,IF(ISNUMBER(--MID(A33,_xlfn.SEQUENCE(LEN(A33)),1)),MID(A33,_xlfn.SEQUENCE(LEN(A33)),1),""))),"")} -> 8732 | J33: 18072.18 | K33: 3012.03 | L33: 21084.21 | N33: (blank) | O33: 250817.6
F34: {=IF(ISNUMBER(SEARCH("Totals",A34)),VALUE(_xlfn.TEXTJOIN("",TRUE,IF(ISNUMBER(--MID(A34,_xlfn.SEQUENCE(LEN(A34)),1)),MID(A34,_xlfn.SEQUENCE(LEN(A34)),1),""))),"")} | N34: Grand Total | O34: 1561006.7
A35: Quikserve Cajun, Inc : 8972 - Vacaville | F35: {=IF(ISNUMBER(SEARCH("Totals",A35)),VALUE(_xlfn.TEXTJOIN("",TRUE,IF(ISNUMBER(--MID(A35,_xlfn.SEQUENCE(LEN(A35)),1)),MID(A35,_xlfn.SEQUENCE(LEN(A35)),1),""))),"")} | I35: B/F | L35: 5020.59
B36: 46113 | C36: 46113 | D36: 8972 CA RE PTAX 2025-26 / 2ND INS | E36: Bill - Solano County Treasury: 8972 CA PPD REAL_SECURED PROPERTY TAX 2025-26 / 2ND INS PAID (Jun-Nov Amort) | F36: {=IF(ISNUMBER(SEARCH("Totals",A36)),VALUE(_xlfn.TEXTJOIN("",TRUE,IF(ISNUMBER(--MID(A36,_xlfn.SEQUENCE(LEN(A36)),1)),MID(A36,_xlfn.SEQUENCE(LEN(A36)),1),""))),"")} | G36: 8972 | H36: 2189 | I36: APJ | J36: 15061.29 | L36: 20081.88
B37: 46142 | C37: 46142 | E37: PLK PREPAID REAL PROPERTY TAX (DEC 2025 - MAY 2026) AMORT - 5/6 | F37: {=IF(ISNUMBER(SEARCH("Totals",A37)),VALUE(_xlfn.TEXTJOIN("",TRUE,IF(ISNUMBER(--MID(A37,_xlfn.SEQUENCE(LEN(A37)),1)),MID(A37,_xlfn.SEQUENCE(LEN(A37)),1),""))),"")} | G37: 8972 | H37: 11760 | I37: GJ | K37: 2510.3 | L37: 17571.58
A38: Totals for Quikserve Cajun, Inc : 8972 - Vacaville | F38: {=IF(ISNUMBER(SEARCH("Totals",A38)),VALUE(_xlfn.TEXTJOIN("",TRUE,IF(ISNUMBER(--MID(A38,_xlfn.SEQUENCE(LEN(A38)),1)),MID(A38,_xlfn.SEQUENCE(LEN(A38)),1),""))),"")} -> 8972 | J38: 15061.29 | K38: 2510.3 | L38: 17571.58
F39: {=IF(ISNUMBER(SEARCH("Totals",A39)),VALUE(_xlfn.TEXTJOIN("",TRUE,IF(ISNUMBER(--MID(A39,_xlfn.SEQUENCE(LEN(A39)),1)),MID(A39,_xlfn.SEQUENCE(LEN(A39)),1),""))),"")}
A40: Quikserve Cajun, Inc : 10545 - Citrus Heights | F40: {=IF(ISNUMBER(SEARCH("Totals",A40)),VALUE(_xlfn.TEXTJOIN("",TRUE,IF(ISNUMBER(--MID(A40,_xlfn.SEQUENCE(LEN(A40)),1)),MID(A40,_xlfn.SEQUENCE(LEN(A40)),1),""))),"")} | I40: B/F | L40: 2678.99
...

Sheet Sheet3 (2)
A1: Location | B1: Posted dt. | C1: Doc dt. | E1: Memo/Description | F1: Department | G1: Location | H1: Txn No | I1: JNL | J1: Debit | K1: Credit | L1: Balance | N1: Row Labels | O1: Sum of Balance
A2: Quikserve Cajun, Inc | F2: {=IF(ISNUMBER(SEARCH("Totals",A2)),VALUE(_xlfn.TEXTJOIN("",TRUE,IF(ISNUMBER(--MID(A2,_xlfn.SEQUENCE(LEN(A2)),1)),MID(A2,_xlfn.SEQUENCE(LEN(A2)),1),""))),"")} | I2: B/F | L2: 11270.49 | N2: 11423 | O2: 7446.92 | P2: =SUMIF('Schedule 2026'!B:B,N2,'Schedule 2026'!#REF!) -> #REF!
A3: Quikserve Cajun, Inc : 11949 - Rancho Cordova | F3: {=IF(ISNUMBER(SEARCH("Totals",A3)),VALUE(_xlfn.TEXTJOIN("",TRUE,IF(ISNUMBER(--MID(A3,_xlfn.SEQUENCE(LEN(A3)),1)),MID(A3,_xlfn.SEQUENCE(LEN(A3)),1),""))),"")} | I3: B/F | L3: 5505.79 | N3: 11424 | O3: 5670.85 | P3: =SUMIF('Schedule 2026'!B:B,N3,'Schedule 2026'!#REF!) -> #REF!
B4: 46113 | C4: 46107 | D4: 04012026 Property Tax Reimbursement | E4: Bill - Tom Uong: 11949 CA RENT REAL_SECURED PROPERTY TAX 2025-26 / 2ND INS REIM. PAID (Jun-Nov Amort) | F4: {=IF(ISNUMBER(SEARCH("Totals",A4)),VALUE(_xlfn.TEXTJOIN("",TRUE,IF(ISNUMBER(--MID(A4,_xlfn.SEQUENCE(LEN(A4)),1)),MID(A4,_xlfn.SEQUENCE(LEN(A4)),1),""))),"")} | G4: 11949 | H4: 2189 | I4: APJ | J4: 16517.35 | L4: 22023.14 | N4: 11425 | O4: 6587.91 | P4: =SUMIF('Schedule 2026'!B:B,N4,'Schedule 2026'!#REF!) -> #REF!
B5: 46142 | C5: 46142 | E5: PLK PREPAID (RENT) REAL PROPERTY TAX (DEC 2025 - MAY 2026) AMORT - 5/6 | F5: {=IF(ISNUMBER(SEARCH("Totals",A5)),VALUE(_xlfn.TEXTJOIN("",TRUE,IF(ISNUMBER(--MID(A5,_xlfn.SEQUENCE(LEN(A5)),1)),MID(A5,_xlfn.SEQUENCE(LEN(A5)),1),""))),"")} | G5: 11949 | H5: 11758 | I5: GJ | K5: 2752.89 | L5: 19270.25 | N5: 11580 | O5: 2374.93 | P5: =SUMIF('Schedule 2026'!B:B,N5,'Schedule 2026'!#REF!) -> #REF!
A6: Totals for Quikserve Cajun, Inc : 11949 - Rancho Cordova | F6: {=IF(ISNUMBER(SEARCH("Totals",A6)),VALUE(_xlfn.TEXTJOIN("",TRUE,IF(ISNUMBER(--MID(A6,_xlfn.SEQUENCE(LEN(A6)),1)),MID(A6,_xlfn.SEQUENCE(LEN(A6)),1),""))),"")} -> 11949 | J6: 16517.35 | K6: 2752.89 | L6: 19270.25 | N6: 11949 | O6: 19270.25 | P6: =SUMIF('Schedule 2026'!B:B,N6,'Schedule 2026'!#REF!) -> #REF!
F7: {=IF(ISNUMBER(SEARCH("Totals",A7)),VALUE(_xlfn.TEXTJOIN("",TRUE,IF(ISNUMBER(--MID(A7,_xlfn.SEQUENCE(LEN(A7)),1)),MID(A7,_xlfn.SEQUENCE(LEN(A7)),1),""))),"")} | N7: 12192 | O7: 507.39 | P7: =SUMIF('Schedule 2026'!B:B,N7,'Schedule 2026'!#REF!) -> #REF!
A8: Quikserve Cajun, Inc : 12192 - Stockton | F8: {=IF(ISNUMBER(SEARCH("Totals",A8)),VALUE(_xlfn.TEXTJOIN("",TRUE,IF(ISNUMBER(--MID(A8,_xlfn.SEQUENCE(LEN(A8)),1)),MID(A8,_xlfn.SEQUENCE(LEN(A8)),1),""))),"")} | I8: B/F | L8: 1014.81 | O8: 86631.76 | P8: =SUMIF('Schedule 2026'!B:B,N8,'Schedule 2026'!#REF!) -> #REF!
B9: 46142 | C9: 46142 | E9: PLK PREPAID (RENT) REAL PROPERTY TAX (DEC 2025 - MAY 2026) AMORT - 5/6 | F9: {=IF(ISNUMBER(SEARCH("Totals",A9)),VALUE(_xlfn.TEXTJOIN("",TRUE,IF(ISNUMBER(--MID(A9,_xlfn.SEQUENCE(LEN(A9)),1)),MID(A9,_xlfn.SEQUENCE(LEN(A9)),1),""))),"")} | G9: 12192 | H9: 11758 | I9: GJ | K9: 507.42 | L9: 507.39 | N9: #VALUE! | O9: 27823.42 | P9: =SUMIF('Schedule 2026'!B:B,N9,'Schedule 2026'!#REF!) -> #REF!
A10: Totals for Quikserve Cajun, Inc : 12192 - Stockton | F10: {=IF(ISNUMBER(SEARCH("Totals",A10)),VALUE(_xlfn.TEXTJOIN("",TRUE,IF(ISNUMBER(--MID(A10,_xlfn.SEQUENCE(LEN(A10)),1)),MID(A10,_xlfn.SEQUENCE(LEN(A10)),1),""))),"")} -> 12192 | J10: 0 | K10: 507.42 | L10: 507.39 | N10: Grand Total | O10: 156313.43 | P10: =SUMIF('Schedule 2026'!B:B,N10,'Schedule 2026'!#REF!) -> #REF!
F11: {=IF(ISNUMBER(SEARCH("Totals",A11)),VALUE(_xlfn.TEXTJOIN("",TRUE,IF(ISNUMBER(--MID(A11,_xlfn.SEQUENCE(LEN(A11)),1)),MID(A11,_xlfn.SEQUENCE(LEN(A11)),1),""))),"")} | P11: =SUMIF('Schedule 2026'!B:B,N11,'Schedule 2026'!#REF!) -> #REF!
A12: Quikserve Cajun, Inc : 11580 - Manteca | F12: {=IF(ISNUMBER(SEARCH("Totals",A12)),VALUE(_xlfn.TEXTJOIN("",TRUE,IF(ISNUMBER(--MID(A12,_xlfn.SEQUENCE(LEN(A12)),1)),MID(A12,_xlfn.SEQUENCE(LEN(A12)),1),""))),"")} | I12: B/F | L12: 4749.89 | P12: =SUMIF('Schedule 2026'!B:B,N12,'Schedule 2026'!#REF!) -> #REF!
B13: 46142 | C13: 46142 | E13: PLK PREPAID (RENT) REAL PROPERTY TAX (DEC 2025 - MAY 2026) AMORT - 5/6 | F13: {=IF(ISNUMBER(SEARCH("Totals",A13)),VALUE(_xlfn.TEXTJOIN("",TRUE,IF(ISNUMBER(--MID(A13,_xlfn.SEQUENCE(LEN(A13)),1)),MID(A13,_xlfn.SEQUENCE(LEN(A13)),1),""))),"")} | G13: 11580 | H13: 11758 | I13: GJ | K13: 2374.96 | L13: 2374.93 | P13: =SUMIF('Schedule 2026'!B:B,N13,'Schedule 2026'!#REF!) -> #REF!
A14: Totals for Quikserve Cajun, Inc : 11580 - Manteca | F14: {=IF(ISNUMBER(SEARCH("Totals",A14)),VALUE(_xlfn.TEXTJOIN("",TRUE,IF(ISNUMBER(--MID(A14,_xlfn.SEQUENCE(LEN(A14)),1)),MID(A14,_xlfn.SEQUENCE(LEN(A14)),1),""))),"")} -> 11580 | J14: 0 | K14: 2374.96 | L14: 2374.93 | P14: =SUMIF('Schedule 2026'!B:B,N14,'Schedule 2026'!#REF!) -> #REF!
F15: {=IF(ISNUMBER(SEARCH("Totals",A15)),VALUE(_xlfn.TEXTJOIN("",TRUE,IF(ISNUMBER(--MID(A15,_xlfn.SEQUENCE(LEN(A15)),1)),MID(A15,_xlfn.SEQUENCE(LEN(A15)),1),""))),"")} | P15: =SUMIF('Schedule 2026'!B:B,N15,'Schedule 2026'!#REF!) -> #REF!
A16: Quikserve Cajun, Inc : 11424 - Chico | F16: {=IF(ISNUMBER(SEARCH("Totals",A16)),VALUE(_xlfn.TEXTJOIN("",TRUE,IF(ISNUMBER(--MID(A16,_xlfn.SEQUENCE(LEN(A16)),1)),MID(A16,_xlfn.SEQUENCE(LEN(A16)),1),""))),"")} | I16: B/F | L16: 0 | P16: =SUMIF('Schedule 2026'!B:B,N16,'Schedule 2026'!#REF!) -> #REF!
B17: 46113 | C17: 46096 | D17: 400016355 | E17: Bill - Popeyes Louisiana Kitchen Inc: *2025_PP_INST_2_BUTTE COUNTY TAX COLLECTOR | F17: {=IF(ISNUMBER(SEARCH("Totals",A17)),VALUE(_xlfn.TEXTJOIN("",TRUE,IF(ISNUMBER(--MID(A17,_xlfn.SEQUENCE(LEN(A17)),1)),MID(A17,_xlfn.SEQUENCE(LEN(A17)),1),""))),"")} | G17: 11424 | H17: 2189 | I17: APJ | J17: 110.52 | L17: 110.52 | P17: =SUMIF('Schedule 2026'!B:B,N17,'Schedule 2026'!#REF!) -> #REF!
B18: 46113 | C18: 46096 | D18: 400016356 | E18: Bill - Popeyes Louisiana Kitchen Inc: *2025_RE_BUTTE COUNTY TAX COLLECTOR | F18: {=IF(ISNUMBER(SEARCH("Totals",A18)),VALUE(_xlfn.TEXTJOIN("",TRUE,IF(ISNUMBER(--MID(A18,_xlfn.SEQUENCE(LEN(A18)),1)),MID(A18,_xlfn.SEQUENCE(LEN(A18)),1),""))),"")} | G18: 11424 | H18: 2189 | I18: APJ | J18: 5560.33 | L18: 5670.85 | P18: =SUMIF('Schedule 2026'!B:B,N18,'Schedule 2026'!#REF!) -> #REF!
A19: Totals for Quikserve Cajun, Inc : 11424 - Chico | F19: {=IF(ISNUMBER(SEARCH("Totals",A19)),VALUE(_xlfn.TEXTJOIN("",TRUE,IF(ISNUMBER(--MID(A19,_xlfn.SEQUENCE(LEN(A19)),1)),MID(A19,_xlfn.SEQUENCE(LEN(A19)),1),""))),"")} -> 11424 | J19: 5670.85 | K19: 0 | L19: 5670.85 | P19: =SUMIF('Schedule 2026'!B:B,N19,'Schedule 2026'!#REF!) -> #REF!
F20: {=IF(ISNUMBER(SEARCH("Totals",A20)),VALUE(_xlfn.TEXTJOIN("",TRUE,IF(ISNUMBER(--MID(A20,_xlfn.SEQUENCE(LEN(A20)),1)),MID(A20,_xlfn.SEQUENCE(LEN(A20)),1),""))),"")} | P20: =SUMIF('Schedule 2026'!B:B,N20,'Schedule 2026'!#REF!) -> #REF!
A21: Totals for Quikserve Cajun, Inc | F21: {=IF(ISNUMBER(SEARCH("Totals",A21)),VALUE(_xlfn.TEXTJOIN("",TRUE,IF(ISNUMBER(--MID(A21,_xlfn.SEQUENCE(LEN(A21)),1)),MID(A21,_xlfn.SEQUENCE(LEN(A21)),1),""))),"")} -> #VALUE! | J21: 22188.2 | K21: 5635.27 | L21: 27823.42 | P21: =SUMIF('Schedule 2026'!B:B,N21,'Schedule 2026'!#REF!) -> #REF!
F22: {=IF(ISNUMBER(SEARCH("Totals",A22)),VALUE(_xlfn.TEXTJOIN("",TRUE,IF(ISNUMBER(--MID(A22,_xlfn.SEQUENCE(LEN(A22)),1)),MID(A22,_xlfn.SEQUENCE(LEN(A22)),1),""))),"")} | P22: =SUMIF('Schedule 2026'!B:B,N22,'Schedule 2026'!#REF!) -> #REF!
A23: Quikserve Management Services Inc. | F23: {=IF(ISNUMBER(SEARCH("Totals",A23)),VALUE(_xlfn.TEXTJOIN("",TRUE,IF(ISNUMBER(--MID(A23,_xlfn.SEQUENCE(LEN(A23)),1)),MID(A23,_xlfn.SEQUENCE(LEN(A23)),1),""))),"")} | I23: B/F | L23: 0 | P23: =SUMIF('Schedule 2026'!B:B,N23,'Schedule 2026'!#REF!) -> #REF!
A24: Quikserve Management Services Inc. : 11423 - Marysville | F24: {=IF(ISNUMBER(SEARCH("Totals",A24)),VALUE(_xlfn.TEXTJOIN("",TRUE,IF(ISNUMBER(--MID(A24,_xlfn.SEQUENCE(LEN(A24)),1)),MID(A24,_xlfn.SEQUENCE(LEN(A24)),1),""))),"")} | I24: B/F | L24: 0 | P24: =SUMIF('Schedule 2026'!B:B,N24,'Schedule 2026'!#REF!) -> #REF!
B25: 46113 | C25: 46096 | D25: 400016354 | E25: Bill - Popeyes Louisiana Kitchen Inc: *2025_RE_INST_2_YUBA COUNTY | F25: {=IF(ISNUMBER(SEARCH("Totals",A25)),VALUE(_xlfn.TEXTJOIN("",TRUE,IF(ISNUMBER(--MID(A25,_xlfn.SEQUENCE(LEN(A25)),1)),MID(A25,_xlfn.SEQUENCE(LEN(A25)),1),""))),"")} | G25: 11423 | H25: 2255 | I25: APJ | J25: 7446.92 | L25: 7446.92 | P25: =SUMIF('Schedule 2026'!B:B,N25,'Schedule 2026'!#REF!) -> #REF!
A26: Totals for Quikserve Management Services Inc. : 11423 - Marysville | F26: {=IF(ISNUMBER(SEARCH("Totals",A26)),VALUE(_xlfn.TEXTJOIN("",TRUE,IF(ISNUMBER(--MID(A26,_xlfn.SEQUENCE(LEN(A26)),1)),MID(A26,_xlfn.SEQUENCE(LEN(A26)),1),""))),"")} -> 11423 | J26: 7446.92 | K26: 0 | L26: 7446.92 | P26: =SUMIF('Schedule 2026'!B:B,N26,'Schedule 2026'!#REF!) -> #REF!
F27: {=IF(ISNUMBER(SEARCH("Totals",A27)),VALUE(_xlfn.TEXTJOIN("",TRUE,IF(ISNUMBER(--MID(A27,_xlfn.SEQUENCE(LEN(A27)),1)),MID(A27,_xlfn.SEQUENCE(LEN(A27)),1),""))),"")} | P27: =SUMIF('Schedule 2026'!B:B,N27,'Schedule 2026'!#REF!) -> #REF!
A28: Quikserve Management Services Inc. : 11425 - Oroville | F28: {=IF(ISNUMBER(SEARCH("Totals",A28)),VALUE(_xlfn.TEXTJOIN("",TRUE,IF(ISNUMBER(--MID(A28,_xlfn.SEQUENCE(LEN(A28)),1)),MID(A28,_xlfn.SEQUENCE(LEN(A28)),1),""))),"")} | I28: B/F | L28: 0 | P28: =SUMIF('Schedule 2026'!B:B,N28,'Schedule 2026'!#REF!) -> #REF!
B29: 46113 | C29: 46096 | D29: 400016357 | E29: Bill - Popeyes Louisiana Kitchen Inc: *2025_PP_INST_2_BUTTE COUNTY TAX COLLECTOR | F29: {=IF(ISNUMBER(SEARCH("Totals",A29)),VALUE(_xlfn.TEXTJOIN("",TRUE,IF(ISNUMBER(--MID(A29,_xlfn.SEQUENCE(LEN(A29)),1)),MID(A29,_xlfn.SEQUENCE(LEN(A29)),1),""))),"")} | G29: 11425 | H29: 2255 | I29: APJ | J29: 98.87 | L29: 98.87 | P29: =SUMIF('Schedule 2026'!B:B,N29,'Schedule 2026'!#REF!) -> #REF!
B30: 46113 | C30: 46096 | D30: 400016358 | E30: Bill - Popeyes Louisiana Kitchen Inc: *2025_RE_BUTTE COUNTY TAX COLLECTOR | F30: {=IF(ISNUMBER(SEARCH("Totals",A30)),VALUE(_xlfn.TEXTJOIN("",TRUE,IF(ISNUMBER(--MID(A30,_xlfn.SEQUENCE(LEN(A30)),1)),MID(A30,_xlfn.SEQUENCE(LEN(A30)),1),""))),"")} | G30: 11425 | H30: 2255 | I30: APJ | J30: 6489.04 | L30: 6587.91 | P30: =SUMIF('Schedule 2026'!B:B,N30,'Schedule 2026'!#REF!) -> #REF!
A31: Totals for Quikserve Management Services Inc. : 11425 - Oroville | F31: {=IF(ISNUMBER(SEARCH("Totals",A31)),VALUE(_xlfn.TEXTJOIN("",TRUE,IF(ISNUMBER(--MID(A31,_xlfn.SEQUENCE(LEN(A31)),1)),MID(A31,_xlfn.SEQUENCE(LEN(A31)),1),""))),"")} -> 11425 | J31: 6587.91 | K31: 0 | L31: 6587.91
A33: Totals for Quikserve Management Services Inc. | J33: 14034.83 | K33: 0 | L33: 14034.83
