Workbook

Sheet Sales
A1: Store | B1: Date | C1: Net Sales | D1: Sales Tax | E1: Refunds | F1: Promo | G1: Discounts | H1: Paid Out | I1: Gift Card Redeemed | J1: Gift Cards Sold | K1: Mobile CC | L1: Mastercard | M1: Visa | N1: Discover | O1: Amex | P1: Debit | Q1: Cash +/- | R1: Deletion $ | S1: Transaction Count | T1: Deposit 1 | U1: Deposit 2 | V1: Deposit 3 | W1: Register Sales | X1: Gross Sales | Y1: Paid Out | Z1: Acct Cash | AA1: Prior Year Net Sales | AB1: Hourly Labor Hours | AC1: Hourly Labor Dollars | AD1: Salaried Labor Hours | AE1: Salaried Labor Dollars | AF1: McLane Orders | AG1: GH Delivery Total | AH1: GH Mobile Total | AI1: Register Sales with donations | AJ1: Grub Hub Payments | AK1: Uber Sales | AL1: Uber Payments | AM1: DoorDash Net Sales | AN1: DoorDash Markup | AO1: DoorDash Payment | AP1: Donation | AQ1: Credit Card Other | AR1: TB Mobile App
A2: 37014 | B2: 05/26/2026 | C2: 4072.64 | D2: 335.96 | E2: 0 | F2: 0 | G2: 71.64 | H2: 0 | I2: -15.89 | J2: 0 | K2: -745.42 | L2: 422.04 | M2: 2679.96 | N2: 81.73 | O2: 45.3 | Q2: -1.5 | R2: 168.32 | S2: 288 | T2: 1168 | U2: 0 | V2: 0 | W2: 4486.06 | X2: 4129.98 | Y2: 0 | Z2: 1169.5 | AA2: 3500.78 | AB2: 56.49 | AC2: 1168.71 | AD2: 0 | AE2: 0 | AF2: 0 | AG2: 0 | AH2: 0 | AI2: 0 | AJ2: 0 | AK2: 0 | AL2: 0 | AM2: 0 | AN2: 0 | AO2: 0 | AP2: 5.82 | AQ2: 0 | AR2: 703.28
A3: 37171 | B3: 05/26/2026 | C3: 3325.13 | D3: 290.26 | E3: 11.98 | F3: 0 | G3: 95.02 | H3: 0 | I3: -15 | J3: 0 | K3: -546.09 | L3: 409.77 | M3: 1857.32 | N3: 27.95 | O3: 5.97 | Q3: -0.79 | R3: 165.29 | S3: 254 | T3: 1055 | U3: 0 | V3: 0 | W3: 3724.15 | X3: 3420.83 | Y3: 0 | Z3: 1055.79 | AA3: 3685.61 | AB3: 59.01 | AC3: 1266.58 | AD3: 0 | AE3: 0 | AF3: 0 | AG3: 0 | AH3: 0 | AI3: 0 | AJ3: 0 | AK3: 91.49 | AL3: 91.49 | AM3: 126.81 | AN3: 25.36 | AO3: 165.84 | AP3: 13.74 | AQ3: 0 | AR3: 501.19
A4: 36224 | B4: 05/26/2026 | C4: 5130.87 | D4: 410.72 | E4: 0 | F4: 0 | G4: 142.86 | H4: 0 | I4: -16.12 | J4: 10 | K4: -1310.06 | L4: 590.68 | M4: 3467.34 | N4: 56.43 | O4: 70.05 | Q4: -38.85 | R4: 374.23 | S4: 350 | T4: 648.61 | U4: 0 | V4: 0 | W4: 5703.31 | X4: 5282.59 | Y4: 0 | Z4: 687.46 | AA4: 5340.52 | AB4: 74.03 | AC4: 1529.2 | AD4: 0 | AE4: 0 | AF4: 3385.71 | AG4: 46.58 | AH4: 0 | AI4: 0 | AJ4: 50.37 | AK4: 56.33 | AL4: 56.33 | AM4: 435.98 | AN4: 87.2 | AO4: 565.67 | AP4: 8.86 | AQ4: 0 | AR4: 1211.69
A5: 30256 | B5: 05/26/2026 | C5: 5789.49 | D5: 463.5 | E5: 0 | F5: 0 | G5: 124.31 | H5: 0 | I5: 0 | J5: 0 | K5: -1104.26 | L5: 554.59 | M5: 3764.02 | N5: 78.72 | O5: 199.38 | Q5: -2 | R5: 193.31 | S5: 411 | T5: 1076 | U5: 0 | V5: 0 | W5: 6393.73 | X5: 5930.23 | Y5: 0 | Z5: 1078 | AA5: 4756.32 | AB5: 71.79 | AC5: 1482.66 | AD5: 0 | AE5: 0 | AF5: 0 | AG5: 0 | AH5: 0 | AI5: 0 | AJ5: 0 | AK5: 52.28 | AL5: 52.28 | AM5: 418.05 | AN5: 83.61 | AO5: 542.43 | AP5: 16.43 | AQ5: 0 | AR5: 1021.27
A6: 40404 | B6: 05/26/2026 | C6: 6086.02 | D6: 0 | E6: 0 | F6: 5.58 | G6: 272.95 | H6: 0 | I6: -18.56 | J6: 0 | K6: -832.76 | L6: 653.31 | M6: 3578.68 | N6: 73.08 | O6: 78.98 | Q6: -7.36 | R6: 625.77 | S6: 434 | T6: 966 | U6: 0 | V6: 0 | W6: 6376.99 | X6: 6367.22 | Y6: 0 | Z6: 973.36 | AA6: 0 | AB6: 94.52 | AC6: 1706.57 | AD6: 0 | AE6: 0 | AF6: 0 | AG6: 37.25 | AH6: 0 | AI6: 0 | AJ6: 37.25 | AK6: 272.1 | AL6: 272.1 | AM6: 344.28 | AN6: 68.86 | AO6: 413.14 | AP6: 12.44 | AQ6: 0 | AR6: 829.77
A7: 29423 | B7: 05/26/2026 | C7: 4437.27 | D7: 364.8 | E7: 0 | F7: 0 | G7: 70.6 | H7: 0 | I7: 0 | J7: 0 | K7: -912.83 | L7: 972.45 | M7: 2380.77 | N7: 88.26 | O7: 62.52 | Q7: -637.5 | R7: 119.9 | S7: 308 | T7: 535 | U7: 0 | V7: 0 | W7: 4886.47 | X7: 4521.67 | Y7: 0 | Z7: 1172.5 | AA7: 4261.18 | AB7: 54.56 | AC7: 1178.7 | AD7: 0 | AE7: 0 | AF7: 0 | AG7: 0 | AH7: 0 | AI7: 0 | AJ7: 0 | AK7: 16.75 | AL7: 16.75 | AM7: 94.39 | AN7: 18.88 | AO7: 122.62 | AP7: 13.8 | AQ7: 0 | AR7: 829.54
A8: 33444 | B8: 05/26/2026 | C8: 2589.59 | D8: 187.74 | E8: 0 | F8: 0 | G8: 65.95 | H8: 0 | I8: 0 | J8: 0 | K8: -300.61 | L8: 313.73 | M8: 1845.18 | N8: 43.36 | O8: 0 | Q8: -0.51 | R8: 107.2 | S8: 188 | T8: 582 | U8: 0 | V8: 0 | W8: 2850.73 | X8: 2662.99 | Y8: 0 | Z8: 582.51 | AA8: 2631.94 | AB8: 46.07 | AC8: 962.12 | AD8: 0 | AE8: 0 | AF8: 0 | AG8: 0 | AH8: 0 | AI8: 0 | AJ8: 0 | AK8: 0 | AL8: 0 | AM8: 0 | AN8: 0 | AO8: 0 | AP8: 7.45 | AQ8: 0 | AR8: 269.01
A9: 30491 | B9: 05/26/2026 | C9: 4455.23 | D9: 389.13 | E9: 0 | F9: 0 | G9: 201.65 | H9: 0 | I9: -36.6 | J9: 0 | K9: -821.47 | L9: 764.83 | M9: 2864.73 | N9: 38.95 | O9: 186.03 | Q9: -1.15 | R9: 145.04 | S9: 333 | T9: 893 | U9: 0 | V9: 0 | W9: 5074.21 | X9: 4685.08 | Y9: 0 | Z9: 894.15 | AA9: 4015.69 | AB9: 57.44 | AC9: 1281.61 | AD9: 0 | AE9: 0 | AF9: 0 | AG9: 0 | AH9: 0 | AI9: 0 | AJ9: 0 | AK9: 0 | AL9: 0 | AM9: 66.88 | AN9: 13.38 | AO9: 87.27 | AP9: 28.2 | AQ9: 0 | AR9: 764.47
A10: 32680 | B10: 05/26/2026 | C10: 5087.01 | D10: 418.82 | E10: 10.88 | F10: 3.69 | G10: 199.74 | H10: 0 | I10: 0 | J10: 0 | K10: -608.27 | L10: 434.24 | M10: 3142.82 | N10: 81.92 | O10: 9.3 | Q10: -1.88 | R10: 293.47 | S10: 378 | T10: 1432 | U10: 0 | V10: 0 | W10: 5734.78 | X10: 5304.18 | Y10: 0 | Z10: 1433.88 | AA10: 5860.16 | AB10: 87.04 | AC10: 1833.76 | AD10: 0 | AE10: 0 | AF10: 0 | AG10: 0 | AH10: 0 | AI10: 0 | AJ10: 0 | AK10: 10.98 | AL10: 10.98 | AM10: 321.93 | AN10: 64.39 | AO10: 418.21 | AP10: 25.52 | AQ10: 0 | AR10: 561.97
A11: 37718 | B11: 05/26/2026 | C11: 3799.11 | D11: 0 | E11: 1.79 | F11: 0 | G11: 99.02 | H11: 0 | I11: -5.38 | J11: 0 | K11: -520.66 | L11: 717.12 | M11: 2220.89 | N11: 0 | O11: 58.3 | Q11: 4.97 | R11: 68.78 | S11: 271 | T11: 602 | U11: 0 | V11: 0 | W11: 3899.44 | X11: 3872.42 | Y11: 0 | Z11: 597.03 | AA11: 3223.9 | AB11: 69.17 | AC11: 1248.42 | AD11: 0 | AE11: 0 | AF11: 5090.79 | AG11: 0 | AH11: 0 | AI11: 0 | AJ11: 0 | AK11: 12.43 | AL11: 12.43 | AM11: 157.73 | AN11: 31.55 | AO11: 189.27 | AP11: 1.31 | AQ11: 0 | AR11: 496.19
A12: 37732 | B12: 05/26/2026 | C12: 5233.61 | D12: 433.88 | E12: 0 | F12: 0 | G12: 176.73 | H12: 0 | I12: -20.29 | J12: 0 | K12: -1088.86 | L12: 668.14 | M12: 3059.33 | N12: 166.27 | O12: 217.7 | Q12: -0.01 | R12: 197.24 | S12: 374 | T12: 715 | U12: 0 | V12: 0 | W12: 5856.19 | X12: 5422.31 | Y12: 0 | Z12: 715.01 | AA12: 0 | AB12: 84.5 | AC12: 1772.82 | AD12: 0 | AE12: 0 | AF12: 0 | AG12: 17.66 | AH12: 0 | AI12: 0 | AJ12: 19.14 | AK12: 51.33 | AL12: 51.33 | AM12: 586.39 | AN12: 117.28 | AO12: 762.25 | AP12: 11.97 | AQ12: 0 | AR12: 1011.68
A13: 34793 | B13: 05/26/2026 | C13: 4329.39 | D13: 382.34 | E13: 5.99 | F13: 3.19 | G13: 133.87 | H13: 0 | I13: -14.66 | J13: 15 | K13: -985.78 | L13: 466.51 | M13: 3096.72 | N13: 85.72 | O13: 76.05 | Q13: -1.71 | R13: 216.79 | S13: 337 | T13: 896 | U13: 0 | V13: 0 | W13: 4893.13 | X13: 4489.26 | Y13: 0 | Z13: 897.71 | AA13: 4775.38 | AB13: 63.23 | AC13: 1447.43 | AD13: 0 | AE13: 0 | AF13: 0 | AG13: 0 | AH13: 0 | AI13: 0 | AJ13: 0 | AK13: 69.75 | AL13: 69.75 | AM13: 37.44 | AN13: 7.49 | AO13: 48.95 | AP13: 29.34 | AQ13: 0 | AR13: 918.04
... A40: 32952 | B40: 05/26/2026 | C40: 5845.93 | D40: 440.07 | E40: 32.49 | F40: 25.62 | G40: 127.55 | H40: 0 | I40: -13.02 | J40: 0 | K40: -1070.62 | L40: 489.47 | M40: 4366.8 | N40: 148.38 | O40: 96.16 | Q40: 0.23 | R40: 208.98 | S40: 441 | T40: 920 | U40: 0 | V40: 0 | W40: 6461.36 | X40: 5970.84 | Y40: 0 | Z40: 919.77 | AA40: 6749.88 | AB40: 97.49 | AC40: 1959.82 | AD40: 0 | AE40: 0 | AF40: 0 | AG40: 0 | AH40: 0 | AI40: 0 | AJ40: 0 | AK40: 58.86 | AL40: 58.86 | AM40: 179.78 | AN40: 35.96 | AO40: 215.73 | AP40: 22.19 | AQ40: 0 | AR40: 998.3

Sheet EBT AMOUNTS
A1: Product Code | B1: Site ID (BE) | C1: Funded Date | D1: Site Alternate ID | E1: Site Name | F1: Major Category | G1: Processed Currency | H1: Transaction Count | I1: Processed Transaction Amount | L1: LOCATION
A2: ElectronicBenefitsTransfer | B2: 498467401887 | C2: 46169 | E2: TACO BELL #28843 | F2: Deposits | G2: USD | H2: 2 | I2: 20.44 | L2: =RIGHT(E2,5) -> 28843
A3: ElectronicBenefitsTransfer | B3: 498474176886 | C3: 46169 | E3: TACO BELL #28844 | F3: Deposits | G3: USD | H3: 2 | I3: 15.28 | L3: =RIGHT(E3,5) -> 28844
A4: ElectronicBenefitsTransfer | B4: 498467386880 | C4: 46169 | E4: TACO BELL #30256 | F4: Deposits | G4: USD | H4: 2 | I4: 34.04 | L4: =RIGHT(E4,5) -> 30256
A5: ElectronicBenefitsTransfer | B5: 498467397887 | C5: 46169 | E5: TACO BELL #30491 | F5: Deposits | G5: USD | H5: 1 | I5: 7.58 | L5: =RIGHT(E5,5) -> 30491
A6: ElectronicBenefitsTransfer | B6: 498474172885 | C6: 46169 | E6: TACO BELL #28841 | F6: Deposits | G6: USD | H6: 1 | I6: 49.28 | L6: =RIGHT(E6,5) -> 28841
A7: ElectronicBenefitsTransfer | B7: 498467400889 | C7: 46169 | E7: TACO BELL #28845 | F7: Deposits | G7: USD | H7: 3 | I7: 30.24 | L7: =RIGHT(E7,5) -> 28845
A8: ElectronicBenefitsTransfer | B8: 498467398885 | C8: 46169 | E8: TACO BELL #36224 | F8: Deposits | G8: USD | H8: 2 | I8: 20.15 | L8: =RIGHT(E8,5) -> 36224
A9: ElectronicBenefitsTransfer | B9: 498474173883 | C9: 46169 | E9: TACO BELL #28846 | F9: Deposits | G9: USD | H9: 8 | I9: 108.77 | L9: =RIGHT(E9,5) -> 28846
A13: Sales Day
A14: ='Daily Sales Taco Bell 03-14 202'!B2 -> 05/26/2026
A17: {=_xlfn.LET( _xlpm.data,_xlfn._xlws.FILTER( 'Daily Sales Taco Bell RED'!D:K, ((('Daily Sales Taco Bell RED'!I:I<>0)+('Daily Sales Taco Bell RED'!J:J<>0))* ISNUMBER(MATCH('Daily Sales Taco Bell RED'!H:H,{28841,28843,28844,28845,28846,30256,30491,36224},0))* (('Daily Sales Taco Bell RED'!E:E="Cash Expected Deposit")+('Daily Sales Taco Bell RED'!E:E="EBT Expected Deposit"))) ), _xlpm.memoCol,INDEX(_xlpm.data,,2), _xlpm.locCol,INDEX(_xlpm.data,,5), _xlpm.sortGroup, IF(_xlpm.memoCol="Cash Expected Deposit",1, IF(_xlpm.memoCol="EBT Expected Deposit",2,0)), _xlpm.sorted,_xlfn.SORTBY(_xlpm.data,_xlpm.sortGroup,1,_xlpm.locCol,1), _xlfn.HSTACK( INDEX(_xlpm.sorted,,1), INDEX(_xlpm.sorted,,2), IF(INDEX(_xlpm.sorted,,3)=0,"",INDEX(_xlpm.sorted,,3)), INDEX(_xlpm.sorted,,4), INDEX(_xlpm.sorted,,5), IF(INDEX(_xlpm.sorted,,6)=0,"",INDEX(_xlpm.sorted,,6)), IF(INDEX(_xlpm.sorted,,7)=0,"",INDEX(_xlpm.sorted,,7)), IF(INDEX(_xlpm.sorted,,8)=0,"",INDEX(_xlpm.sorted,,8)) ) )} -> POS Data Upload Sabretooth | B17: Cash Expected Deposit | D17: 101900 | E17: 28841 | F17: 972.28
A18: POS Data Upload Sabretooth | B18: Cash Expected Deposit | D18: 101900 | E18: 28843 | F18: 1153.01
A19: POS Data Upload Sabretooth | B19: Cash Expected Deposit | D19: 101900 | E19: 28844 | F19: 2627.77
A20: POS Data Upload Sabretooth | B20: Cash Expected Deposit | D20: 101900 | E20: 28845 | F20: 1159.12
A21: POS Data Upload Sabretooth | B21: Cash Expected Deposit | D21: 101900 | E21: 28846 | F21: 1491.03
A22: POS Data Upload Sabretooth | B22: Cash Expected Deposit | D22: 101900 | E22: 30256 | F22: 1043.96
A23: POS Data Upload Sabretooth | B23: Cash Expected Deposit | D23: 101900 | E23: 30491 | F23: 886.57
A24: POS Data Upload Sabretooth | B24: Cash Expected Deposit | D24: 101900 | E24: 36224 | F24: 667.31
A25: POS Data Upload Sabretooth | B25: EBT Expected Deposit | D25: 111200 | E25: 28841 | F25: 49.28
A26: POS Data Upload Sabretooth | B26: EBT Expected Deposit | D26: 111200 | E26: 28843 | F26: 20.44
A27: POS Data Upload Sabretooth | B27: EBT Expected Deposit | D27: 111200 | E27: 28844 | F27: 15.28
A28: POS Data Upload Sabretooth | B28: EBT Expected Deposit | D28: 111200 | E28: 28845 | F28: 30.24
A29: POS Data Upload Sabretooth | B29: EBT Expected Deposit | D29: 111200 | E29: 28846 | F29: 108.77
... A32: POS Data Upload Sabretooth | B32: EBT Expected Deposit | D32: 111200 | E32: 36224 | F32: 20.15

Sheet Conciliation
A1: Store | C1: Sales TAX | D1: Gross Sales POS | E1: Discounts | F1: Promo | G1: Donations | H1: Net Sales | I1: Sales TAX | J1: GC Sold | K1: Paid Out | L1: Paid In | M1: Donation | N1: Total Revenue | O1: Mastercard | P1: Visa | Q1: Discover | R1: Amex | S1: Debit | U1: EBT | V1: GC Redeem | W1: Acct Cash | X1: Deposits | Y1: GH | Z1: Uber | AA1: DD | AB1: CC Totals | AC1: Payments Total | AD1: O/S | AE1: OS | AH1: Deposit 1 | AI1: Deposit 2 | AJ1: Deposit 3 | AK1: Cash +/- | AL1: Cash Expected | AM1: Difference
A2: 28841 | C2: =_xlfn.XLOOKUP($A2,Sales!$A:$A,Sales!$D:$D,"0") -> 392.96 | D2: =SUM(H2+F2+E2-Z2,"0") -> 5040.05 | E2: =_xlfn.XLOOKUP($A2,Sales!$A:$A,Sales!$G:$G,"0") -> 151.86 | F2: =_xlfn.XLOOKUP($A2,Sales!$A:$A,Sales!$F:$F,"0") -> 3.19 | G2: =_xlfn.XLOOKUP($A2,Sales!$A:$A,Sales!$AP:$AP,"0") -> 21.59 | H2: =_xlfn.XLOOKUP($A2,Sales!$A:$A,Sales!$C:$C,"0") -> 4931.78 | I2: =C2 -> 392.96 | J2: =_xlfn.XLOOKUP($A2,Sales!$A:$A,Sales!$J:$J,"0") -> 15 | K2: =_xlfn.XLOOKUP($A2,Sales!$A:$A,Sales!$H:$H,"0") -> 28.9 | L2: 0 | M2: =_xlfn.XLOOKUP($A2,Sales!$A:$A,Sales!$AP:$AP,"0") -> 21.59 | N2: =H2+I2+J2+M2+L2-K2 -> 5332.43 | O2: =_xlfn.XLOOKUP($A2,Sales!$A:$A,Sales!$L:$L,"0") -> 509.08 | P2: =_xlfn.XLOOKUP($A2,Sales!$A:$A,Sales!$M:$M,"0") -> 2813.72 | Q2: =_xlfn.XLOOKUP($A2,Sales!$A:$A,Sales!$N:$N,"0") -> 109.1 | R2: =_xlfn.XLOOKUP($A2,Sales!$A:$A,Sales!$O:$O,"0") -> 120.76 | S2: =_xlfn.XLOOKUP($A2,Sales!$A:$A,Sales!$P:$P,"0") -> 0 | U2: =SUMIFS('EBT AMOUNTS'!I:I,'EBT AMOUNTS'!L:L,Conciliation!A2) -> 49.28 | V2: =_xlfn.XLOOKUP($A2,Sales!$A:$A,Sales!$I:$I,"0")*-1 -> 5.1 | W2: =_xlfn.XLOOKUP($A2,Sales!$A:$A,Sales!$Z:$Z,"0")-K2-U2 -> 972.28 | X2: {=_xlfn.XLOOKUP($A2,Sales!$A:$A,Sales!$T:$T+Sales!$U:$U+Sales!$V:$V,"0")} -> 1021 | Y2: =_xlfn.XLOOKUP($A2,Sales!$A:$A,Sales!$AJ:$AJ,"0") -> 0 | Z2: =_xlfn.XLOOKUP($A2,Sales!$A:$A,Sales!$AL:$AL,"0") -> 46.78 | AA2: =_xlfn.XLOOKUP($A2,Sales!$A:$A,Sales!$AO:$AO,"0") -> 706.33 | AB2: =O2+P2+Q2+S2 -> 3431.9 | AC2: =O2+P2+Q2+R2+S2+V2+W2+Y2+Z2+AA2+U2 -> 5332.43 | AD2: =N2-AC2 -> 0 | AE2: =_xlfn.XLOOKUP($A2,Sales!$A:$A,Sales!$Q:$Q,"0") -> -0.56 | AG2: 28841 | AH2: =VLOOKUP(AG2,Sales!A:V,20,FALSE) -> 1021 | AI2: =VLOOKUP(AG2,Sales!A:U,21,FALSE) -> 0 | AJ2: =VLOOKUP(AG2,Sales!A:V,22,FALSE) -> 0 | AK2: =VLOOKUP(AG2,Sales!A:Q,17,FALSE) -> -0.56 | AL2: =SUMIF(A:A,AG2,W:W) -> 972.28 | AM2: =AL2-(AH2+AI2+AJ2)+AK2+U2 -> 8.5265128e-14
A3: 28842 | C3: =_xlfn.XLOOKUP($A3,Sales!$A:$A,Sales!$D:$D,"0") -> 567.13 | D3: =SUM(H3+F3+E3-Z3,"0") -> 6973.73 | E3: =_xlfn.XLOOKUP($A3,Sales!$A:$A,Sales!$G:$G,"0") -> 202.13 | F3: =_xlfn.XLOOKUP($A3,Sales!$A:$A,Sales!$F:$F,"0") -> 0 | G3: =_xlfn.XLOOKUP($A3,Sales!$A:$A,Sales!$AP:$AP,"0") -> 37.8 | H3: =_xlfn.XLOOKUP($A3,Sales!$A:$A,Sales!$C:$C,"0") -> 6909.03 | I3: =C3 -> 567.13 | J3: =_xlfn.XLOOKUP($A3,Sales!$A:$A,Sales!$J:$J,"0") -> 0 | K3: =_xlfn.XLOOKUP($A3,Sales!$A:$A,Sales!$H:$H,"0") -> 0 | L3: 0 | M3: =_xlfn.XLOOKUP($A3,Sales!$A:$A,Sales!$AP:$AP,"0") -> 37.8 | N3: =H3+I3+J3+M3+L3-K3 -> 7513.96 | O3: =_xlfn.XLOOKUP($A3,Sales!$A:$A,Sales!$L:$L,"0") -> 938.73 | P3: =_xlfn.XLOOKUP($A3,Sales!$A:$A,Sales!$M:$M,"0") -> 4277.42 | Q3: =_xlfn.XLOOKUP($A3,Sales!$A:$A,Sales!$N:$N,"0") -> 108.37 | R3: =_xlfn.XLOOKUP($A3,Sales!$A:$A,Sales!$O:$O,"0") -> 113.84 | S3: =_xlfn.XLOOKUP($A3,Sales!$A:$A,Sales!$P:$P,"0") -> 0 | V3: =_xlfn.XLOOKUP($A3,Sales!$A:$A,Sales!$I:$I,"0")*-1 -> 9.4 | W3: =_xlfn.XLOOKUP($A3,Sales!$A:$A,Sales!$Z:$Z,"0")-K3-U3 -> 1108.08 | X3: {=_xlfn.XLOOKUP($A3,Sales!$A:$A,Sales!$T:$T+Sales!$U:$U+Sales!$V:$V,"0")-K3} -> 1107 | Y3: =_xlfn.XLOOKUP($A3,Sales!$A:$A,Sales!$AJ:$AJ,"0") -> 0 | Z3: =_xlfn.XLOOKUP($A3,Sales!$A:$A,Sales!$AL:$AL,"0") -> 137.43 | AA3: =_xlfn.XLOOKUP($A3,Sales!$A:$A,Sales!$AO:$AO,"0") -> 820.69 | AB3: =O3+P3+Q3+S3 -> 5324.52 | AC3: =O3+P3+Q3+R3+S3+V3+W3+Y3+Z3+AA3+U3 -> 7513.96 | AD3: =N3-AC3 -> 0 | AE3: =_xlfn.XLOOKUP($A3,Sales!$A:$A,Sales!$Q:$Q,"0") -> -1.08 | AG3: 28842 | AH3: =VLOOKUP(AG3,Sales!A:V,20,FALSE) -> 1107 | AI3: =VLOOKUP(AG3,Sales!A:U,21,FALSE) -> 0 | AJ3: =VLOOKUP(AG3,Sales!A:V,22,FALSE) -> 0 | AK3: =VLOOKUP(AG3,Sales!A:Q,17,FALSE) -> -1.08 | AL3: =SUMIF(A:A,AG3,W:W) -> 1108.08 | AM3: =AL3-(AH3+AI3+AJ3)+AK3 -> -7.283063e-14
A4: 28843 | C4: =_xlfn.XLOOKUP($A4,Sales!$A:$A,Sales!$D:$D,"0") -> 482.66 | D4: =SUM(H4+F4+E4-Z4,"0") -> 5473.4 | E4: =_xlfn.XLOOKUP($A4,Sales!$A:$A,Sales!$G:$G,"0") -> 164.27 | F4: =_xlfn.XLOOKUP($A4,Sales!$A:$A,Sales!$F:$F,"0") -> 0 | G4: =_xlfn.XLOOKUP($A4,Sales!$A:$A,Sales!$AP:$AP,"0") -> 22.89 | H4: =_xlfn.XLOOKUP($A4,Sales!$A:$A,Sales!$C:$C,"0") -> 5394.89 | I4: =C4 -> 482.66 | J4: =_xlfn.XLOOKUP($A4,Sales!$A:$A,Sales!$J:$J,"0") -> 0 | K4: =_xlfn.XLOOKUP($A4,Sales!$A:$A,Sales!$H:$H,"0") -> 0 | L4: 0 | M4: =_xlfn.XLOOKUP($A4,Sales!$A:$A,Sales!$AP:$AP,"0") -> 22.89 | N4: =H4+I4+J4+M4+L4-K4 -> 5900.44 | O4: =_xlfn.XLOOKUP($A4,Sales!$A:$A,Sales!$L:$L,"0") -> 467.17 | P4: =_xlfn.XLOOKUP($A4,Sales!$A:$A,Sales!$M:$M,"0") -> 3305.78 | Q4: =_xlfn.XLOOKUP($A4,Sales!$A:$A,Sales!$N:$N,"0") -> 36.84 | R4: =_xlfn.XLOOKUP($A4,Sales!$A:$A,Sales!$O:$O,"0") -> 131.52 | S4: =_xlfn.XLOOKUP($A4,Sales!$A:$A,Sales!$P:$P,"0") -> 0 | U4: =SUMIFS('EBT AMOUNTS'!I:I,'EBT AMOUNTS'!L:L,Conciliation!A4) -> 20.44 | V4: =_xlfn.XLOOKUP($A4,Sales!$A:$A,Sales!$I:$I,"0")*-1 -> 0 | W4: =_xlfn.XLOOKUP($A4,Sales!$A:$A,Sales!$Z:$Z,"0")-K4-U4 -> 1153.01 | X4: {=_xlfn.XLOOKUP($A4,Sales!$A:$A,Sales!$T:$T+Sales!$U:$U+Sales!$V:$V,"0")-K4} -> 1170 | Y4: =_xlfn.XLOOKUP($A4,Sales!$A:$A,Sales!$AJ:$AJ,"0") -> 27.42 | Z4: =_xlfn.XLOOKUP($A4,Sales!$A:$A,Sales!$AL:$AL,"0") -> 85.76 | AA4: =_xlfn.XLOOKUP($A4,Sales!$A:$A,Sales!$AO:$AO,"0") -> 672.5 | AB4: =O4+P4+Q4+S4 -> 3809.79 | AC4: =O4+P4+Q4+R4+S4+V4+W4+Y4+Z4+AA4+U4 -> 5900.44 | AD4: =N4-AC4 -> 0 | AE4: =_xlfn.XLOOKUP($A4,Sales!$A:$A,Sales!$Q:$Q,"0") -> -3.45 | AG4: 28843 | AH4: =VLOOKUP(AG4,Sales!A:V,20,FALSE) -> 1170 | AI4: =VLOOKUP(AG4,Sales!A:U,21,FALSE) -> 0 | AJ4: =VLOOKUP(AG4,Sales!A:V,22,FALSE) -> 0 | AK4: =VLOOKUP(AG4,Sales!A:Q,17,FALSE) -> -3.45 | AL4: =SUMIF(A:A,AG4,W:W) -> 1153.01 | AM4: =AL4-(AH4+AI4+AJ4)+AK4+U4 -> 0
A5: 28844 | C5: =_xlfn.XLOOKUP($A5,Sales!$A:$A,Sales!$D:$D,"0") -> 794.81 | D5: =SUM(H5+F5+E5-Z5,"0") -> 10252.94 | E5: =_xlfn.XLOOKUP($A5,Sales!$A:$A,Sales!$G:$G,"0") -> 315.18 | F5: =_xlfn.XLOOKUP($A5,Sales!$A:$A,Sales!$F:$F,"0") -> 0 | G5: =_xlfn.XLOOKUP($A5,Sales!$A:$A,Sales!$AP:$AP,"0") -> 34.64 | H5: =_xlfn.XLOOKUP($A5,Sales!$A:$A,Sales!$C:$C,"0") -> 10050.16 | I5: =C5 -> 794.81 | J5: =_xlfn.XLOOKUP($A5,Sales!$A:$A,Sales!$J:$J,"0") -> 0 | K5: =_xlfn.XLOOKUP($A5,Sales!$A:$A,Sales!$H:$H,"0") -> 0 | L5: 0 | M5: =_xlfn.XLOOKUP($A5,Sales!$A:$A,Sales!$AP:$AP,"0") -> 34.64 | N5: =H5+I5+J5+M5+L5-K5 -> 10879.61 | O5: =_xlfn.XLOOKUP($A5,Sales!$A:$A,Sales!$L:$L,"0") -> 1094.69 | P5: =_xlfn.XLOOKUP($A5,Sales!$A:$A,Sales!$M:$M,"0") -> 5676.43 | Q5: =_xlfn.XLOOKUP($A5,Sales!$A:$A,Sales!$N:$N,"0") -> 218.19 | R5: =_xlfn.XLOOKUP($A5,Sales!$A:$A,Sales!$O:$O,"0") -> 38.59 | S5: =_xlfn.XLOOKUP($A5,Sales!$A:$A,Sales!$P:$P,"0") -> 0 | U5: =SUMIFS('EBT AMOUNTS'!I:I,'EBT AMOUNTS'!L:L,Conciliation!A5) -> 15.28 | V5: =_xlfn.XLOOKUP($A5,Sales!$A:$A,Sales!$I:$I,"0")*-1 -> 39.25 | W5: =_xlfn.XLOOKUP($A5,Sales!$A:$A,Sales!$Z:$Z,"0")-K5-U5 -> 2627.77 | X5: {=_xlfn.XLOOKUP($A5,Sales!$A:$A,Sales!$T:$T+Sales!$U:$U+Sales!$V:$V,"0")-K5} -> 2642.57 | Y5: =_xlfn.XLOOKUP($A5,Sales!$A:$A,Sales!$AJ:$AJ,"0") -> 0 | Z5: =_xlfn.XLOOKUP($A5,Sales!$A:$A,Sales!$AL:$AL,"0") -> 112.4 | AA5: =_xlfn.XLOOKUP($A5,Sales!$A:$A,Sales!$AO:$AO,"0") -> 1057.01 | AB5: =O5+P5+Q5+S5 -> 6989.31 | AC5: =O5+P5+Q5+R5+S5+V5+W5+Y5+Z5+AA5+U5 -> 10879.61 | AD5: =N5-AC5 -> 0 | AE5: =_xlfn.XLOOKUP($A5,Sales!$A:$A,Sales!$Q:$Q,"0") -> -0.48 | AG5: 28844 | AH5: =VLOOKUP(AG5,Sales!A:V,20,FALSE) -> 2642.57 | AI5: =VLOOKUP(AG5,Sales!A:U,21,FALSE) -> 0 | AJ5: =VLOOKUP(AG5,Sales!A:V,22,FALSE) -> 0 | AK5: =VLOOKUP(AG5,Sales!A:Q,17,FALSE) -> -0.48 | AL5: =SUMIF(A:A,AG5,W:W) -> 2627.77 | AM5: =AL5-(AH5+AI5+AJ5)+AK5+U5 -> -1.8296475e-13
A6: 28845 | C6: =_xlfn.XLOOKUP($A6,Sales!$A:$A,Sales!$D:$D,"0") -> 776.16 | D6: =SUM(H6+F6+E6-Z6,"0") -> 9879.26 | E6: =_xlfn.XLOOKUP($A6,Sales!$A:$A,Sales!$G:$G,"0") -> 298.4 | F6: =_xlfn.XLOOKUP($A6,Sales!$A:$A,Sales!$F:$F,"0") -> 0 | G6: =_xlfn.XLOOKUP($A6,Sales!$A:$A,Sales!$AP:$AP,"0") -> 24.73 | H6: =_xlfn.XLOOKUP($A6,Sales!$A:$A,Sales!$C:$C,"0") -> 9685.93 | I6: =C6 -> 776.16 | J6: =_xlfn.XLOOKUP($A6,Sales!$A:$A,Sales!$J:$J,"0") -> 10 | K6: =_xlfn.XLOOKUP($A6,Sales!$A:$A,Sales!$H:$H,"0") -> 0 | L6: 0 | M6: =_xlfn.XLOOKUP($A6,Sales!$A:$A,Sales!$AP:$AP,"0") -> 24.73 | N6: =H6+I6+J6+M6+L6-K6 -> 10496.82 | O6: =_xlfn.XLOOKUP($A6,Sales!$A:$A,Sales!$L:$L,"0") -> 1040.72 | P6: =_xlfn.XLOOKUP($A6,Sales!$A:$A,Sales!$M:$M,"0") -> 5844.26 | Q6: =_xlfn.XLOOKUP($A6,Sales!$A:$A,Sales!$N:$N,"0") -> 147.04 | R6: =_xlfn.XLOOKUP($A6,Sales!$A:$A,Sales!$O:$O,"0") -> 349.48 | S6: =_xlfn.XLOOKUP($A6,Sales!$A:$A,Sales!$P:$P,"0") -> 0 | U6: =SUMIFS('EBT AMOUNTS'!I:I,'EBT AMOUNTS'!L:L,Conciliation!A6) -> 30.24 | V6: =_xlfn.XLOOKUP($A6,Sales!$A:$A,Sales!$I:$I,"0")*-1 -> 26.25 | W6: =_xlfn.XLOOKUP($A6,Sales!$A:$A,Sales!$Z:$Z,"0")-K6-U6 -> 1159.12 | X6: {=_xlfn.XLOOKUP($A6,Sales!$A:$A,Sales!$T:$T+Sales!$U:$U+Sales!$V:$V,"0")-K6} -> 1178.24 | Y6: =_xlfn.XLOOKUP($A6,Sales!$A:$A,Sales!$AJ:$AJ,"0") -> 90.74 | Z6: =_xlfn.XLOOKUP($A6,Sales!$A:$A,Sales!$AL:$AL,"0") -> 105.07 | AA6: =_xlfn.XLOOKUP($A6,Sales!$A:$A,Sales!$AO:$AO,"0") -> 1703.9 | AB6: =O6+P6+Q6+S6 -> 7032.02 | AC6: =O6+P6+Q6+R6+S6+V6+W6+Y6+Z6+AA6+U6 -> 10496.82 | AD6: =N6-AC6 -> 0 | AE6: =_xlfn.XLOOKUP($A6,Sales!$A:$A,Sales!$Q:$Q,"0") -> -11.12 | AG6: 28845 | AH6: =VLOOKUP(AG6,Sales!A:V,20,FALSE) -> 1178.24 | AI6: =VLOOKUP(AG6,Sales!A:U,21,FALSE) -> 0 | AJ6: =VLOOKUP(AG6,Sales!A:V,22,FALSE) -> 0 | AK6: =VLOOKUP(AG6,Sales!A:Q,17,FALSE) -> -11.12 | AL6: =SUMIF(A:A,AG6,W:W) -> 1159.12 | AM6: =AL6-(AH6+AI6+AJ6)+AK6+U6 -> -1.1723955e-13
A7: 28846 | C7: =_xlfn.XLOOKUP($A7,Sales!$A:$A,Sales!$D:$D,"0") -> 628.61 | D7: =SUM(H7+F7+E7-Z7,"0") -> 7855.45 | E7: =_xlfn.XLOOKUP($A7,Sales!$A:$A,Sales!$G:$G,"0") -> 238 | F7: =_xlfn.XLOOKUP($A7,Sales!$A:$A,Sales!$F:$F,"0") -> 0 | G7: =_xlfn.XLOOKUP($A7,Sales!$A:$A,Sales!$AP:$AP,"0") -> 27.83 | H7: =_xlfn.XLOOKUP($A7,Sales!$A:$A,Sales!$C:$C,"0") -> 7920.15 | I7: =C7 -> 628.61 | J7: =_xlfn.XLOOKUP($A7,Sales!$A:$A,Sales!$J:$J,"0") -> 0 | K7: =_xlfn.XLOOKUP($A7,Sales!$A:$A,Sales!$H:$H,"0") -> 0 | L7: 0 | M7: =_xlfn.XLOOKUP($A7,Sales!$A:$A,Sales!$AP:$AP,"0") -> 27.83 | N7: =H7+I7+J7+M7+L7-K7 -> 8576.59 | O7: =_xlfn.XLOOKUP($A7,Sales!$A:$A,Sales!$L:$L,"0") -> 924.44 | P7: =_xlfn.XLOOKUP($A7,Sales!$A:$A,Sales!$M:$M,"0") -> 3917.32 | Q7: =_xlfn.XLOOKUP($A7,Sales!$A:$A,Sales!$N:$N,"0") -> 83.67 | R7: =_xlfn.XLOOKUP($A7,Sales!$A:$A,Sales!$O:$O,"0") -> 75.28 | S7: =_xlfn.XLOOKUP($A7,Sales!$A:$A,Sales!$P:$P,"0") -> 0 | U7: =SUMIFS('EBT AMOUNTS'!I:I,'EBT AMOUNTS'!L:L,Conciliation!A7) -> 108.77 | V7: =_xlfn.XLOOKUP($A7,Sales!$A:$A,Sales!$I:$I,"0")*-1 -> 9.72 | W7: =_xlfn.XLOOKUP($A7,Sales!$A:$A,Sales!$Z:$Z,"0")-K7-U7 -> 1491.03 | X7: {=_xlfn.XLOOKUP($A7,Sales!$A:$A,Sales!$T:$T+Sales!$U:$U+Sales!$V:$V,"0")-K7} -> 1604.77 | Y7: =_xlfn.XLOOKUP($A7,Sales!$A:$A,Sales!$AJ:$AJ,"0") -> 37.79 | Z7: =_xlfn.XLOOKUP($A7,Sales!$A:$A,Sales!$AL:$AL,"0") -> 302.7 | AA7: =_xlfn.XLOOKUP($A7,Sales!$A:$A,Sales!$AO:$AO,"0") -> 1625.87 | AB7: =O7+P7+Q7+S7 -> 4925.43 | AC7: =O7+P7+Q7+R7+S7+V7+W7+Y7+Z7+AA7+U7 -> 8576.59 | AD7: =N7-AC7 -> 0 | AE7: =_xlfn.XLOOKUP($A7,Sales!$A:$A,Sales!$Q:$Q,"0") -> 4.97 | AG7: 28846 | AH7: =VLOOKUP(AG7,Sales!A:V,20,FALSE) -> 1604.77 | AI7: =VLOOKUP(AG7,Sales!A:U,21,FALSE) -> 0 | AJ7: =VLOOKUP(AG7,Sales!A:V,22,FALSE) -> 0 | AK7: =VLOOKUP(AG7,Sales!A:Q,17,FALSE) -> 4.97 | AL7: =SUMIF(A:A,AG7,W:W) -> 1491.03 | AM7: =AL7-(AH7+AI7+AJ7)+AK7+U7 -> 0
A8: 29423 | C8: =_xlfn.XLOOKUP($A8,Sales!$A:$A,Sales!$D:$D,"0") -> 364.8 | D8: =SUM(H8+F8+E8-Z8,"0") -> 4491.12 | E8: =_xlfn.XLOOKUP($A8,Sales!$A:$A,Sales!$G:$G,"0") -> 70.6 | F8: =_xlfn.XLOOKUP($A8,Sales!$A:$A,Sales!$F:$F,"0") -> 0 | G8: =_xlfn.XLOOKUP($A8,Sales!$A:$A,Sales!$AP:$AP,"0") -> 13.8 | H8: =_xlfn.XLOOKUP($A8,Sales!$A:$A,Sales!$C:$C,"0") -> 4437.27 | I8: =C8 -> 364.8 | J8: =_xlfn.XLOOKUP($A8,Sales!$A:$A,Sales!$J:$J,"0") -> 0 | K8: =_xlfn.XLOOKUP($A8,Sales!$A:$A,Sales!$H:$H,"0") -> 0 | L8: 0 | M8: =_xlfn.XLOOKUP($A8,Sales!$A:$A,Sales!$AP:$AP,"0") -> 13.8 | N8: =H8+I8+J8+M8+L8-K8 -> 4815.87 | O8: =_xlfn.XLOOKUP($A8,Sales!$A:$A,Sales!$L:$L,"0") -> 972.45 | P8: =_xlfn.XLOOKUP($A8,Sales!$A:$A,Sales!$M:$M,"0") -> 2380.77 | Q8: =_xlfn.XLOOKUP($A8,Sales!$A:$A,Sales!$N:$N,"0") -> 88.26 | R8: =_xlfn.XLOOKUP($A8,Sales!$A:$A,Sales!$O:$O,"0") -> 62.52 | S8: =_xlfn.XLOOKUP($A8,Sales!$A:$A,Sales!$P:$P,"0") -> 0 | V8: =_xlfn.XLOOKUP($A8,Sales!$A:$A,Sales!$I:$I,"0")*-1 -> 0 | W8: =_xlfn.XLOOKUP($A8,Sales!$A:$A,Sales!$Z:$Z,"0")-K8-U8 -> 1172.5 | X8: {=_xlfn.XLOOKUP($A8,Sales!$A:$A,Sales!$T:$T+Sales!$U:$U+Sales!$V:$V,"0")-K8} -> 535 | Y8: =_xlfn.XLOOKUP($A8,Sales!$A:$A,Sales!$AJ:$AJ,"0") -> 0 | Z8: =_xlfn.XLOOKUP($A8,Sales!$A:$A,Sales!$AL:$AL,"0") -> 16.75 | AA8: =_xlfn.XLOOKUP($A8,Sales!$A:$A,Sales!$AO:$AO,"0") -> 122.62 | AB8: =O8+P8+Q8+S8 -> 3441.48 | AC8: =O8+P8+Q8+R8+S8+V8+W8+Y8+Z8+AA8+U8 -> 4815.87 | AD8: =N8-AC8 -> 0 | AE8: =_xlfn.XLOOKUP($A8,Sales!$A:$A,Sales!$Q:$Q,"0") -> -637.5 | AG8: 29423 | AH8: =VLOOKUP(AG8,Sales!A:V,20,FALSE) -> 535 | AI8: =VLOOKUP(AG8,Sales!A:U,21,FALSE) -> 0 | AJ8: =VLOOKUP(AG8,Sales!A:V,22,FALSE) -> 0 | AK8: =VLOOKUP(AG8,Sales!A:Q,17,FALSE) -> -637.5 | AL8: =SUMIF(A:A,AG8,W:W) -> 1172.5 | AM8: =AL8-(AH8+AI8+AJ8)+AK8 -> 0
A9: 30256 | C9: =_xlfn.XLOOKUP($A9,Sales!$A:$A,Sales!$D:$D,"0") -> 463.5 | D9: =SUM(H9+F9+E9-Z9,"0") -> 5861.52 | E9: =_xlfn.XLOOKUP($A9,Sales!$A:$A,Sales!$G:$G,"0") -> 124.31 | F9: =_xlfn.XLOOKUP($A9,Sales!$A:$A,Sales!$F:$F,"0") -> 0 | G9: =_xlfn.XLOOKUP($A9,Sales!$A:$A,Sales!$AP:$AP,"0") -> 16.43 | H9: =_xlfn.XLOOKUP($A9,Sales!$A:$A,Sales!$C:$C,"0") -> 5789.49 | I9: =C9 -> 463.5 | J9: =_xlfn.XLOOKUP($A9,Sales!$A:$A,Sales!$J:$J,"0") -> 0 | K9: =_xlfn.XLOOKUP($A9,Sales!$A:$A,Sales!$H:$H,"0") -> 0 | L9: 0 | M9: =_xlfn.XLOOKUP($A9,Sales!$A:$A,Sales!$AP:$AP,"0") -> 16.43 | N9: =H9+I9+J9+M9+L9-K9 -> 6269.42 | O9: =_xlfn.XLOOKUP($A9,Sales!$A:$A,Sales!$L:$L,"0") -> 554.59 | P9: =_xlfn.XLOOKUP($A9,Sales!$A:$A,Sales!$M:$M,"0") -> 3764.02 | Q9: =_xlfn.XLOOKUP($A9,Sales!$A:$A,Sales!$N:$N,"0") -> 78.72 | R9: =_xlfn.XLOOKUP($A9,Sales!$A:$A,Sales!$O:$O,"0") -> 199.38 | S9: =_xlfn.XLOOKUP($A9,Sales!$A:$A,Sales!$P:$P,"0") -> 0 | U9: =SUMIFS('EBT AMOUNTS'!I:I,'EBT AMOUNTS'!L:L,Conciliation!A9) -> 34.04 | V9: =_xlfn.XLOOKUP($A9,Sales!$A:$A,Sales!$I:$I,"0")*-1 -> 0 | W9: =_xlfn.XLOOKUP($A9,Sales!$A:$A,Sales!$Z:$Z,"0")-K9-U9 -> 1043.96 | X9: {=_xlfn.XLOOKUP($A9,Sales!$A:$A,Sales!$T:$T+Sales!$U:$U+Sales!$V:$V,"0")-K9} -> 1076 | Y9: =_xlfn.XLOOKUP($A9,Sales!$A:$A,Sales!$AJ:$AJ,"0") -> 0 | Z9: =_xlfn.XLOOKUP($A9,Sales!$A:$A,Sales!$AL:$AL,"0") -> 52.28 | AA9: =_xlfn.XLOOKUP($A9,Sales!$A:$A,Sales!$AO:$AO,"0") -> 542.43 | AB9: =O9+P9+Q9+S9 -> 4397.33 | AC9: =O9+P9+Q9+R9+S9+V9+W9+Y9+Z9+AA9+U9 -> 6269.42 | AD9: =N9-AC9 -> 0 | AE9: =_xlfn.XLOOKUP($A9,Sales!$A:$A,Sales!$Q:$Q,"0") -> -2 | AG9: 30256 | AH9: =VLOOKUP(AG9,Sales!A:V,20,FALSE) -> 1076 | AI9: =VLOOKUP(AG9,Sales!A:U,21,FALSE) -> 0 | AJ9: =VLOOKUP(AG9,Sales!A:V,22,FALSE) -> 0 | AK9: =VLOOKUP(AG9,Sales!A:Q,17,FALSE) -> -2 | AL9: =SUMIF(A:A,AG9,W:W) -> 1043.96 | AM9: =AL9-(AH9+AI9+AJ9)+AK9+U9 -> 0
A10: 30491 | C10: =_xlfn.XLOOKUP($A10,Sales!$A:$A,Sales!$D:$D,"0") -> 389.13 | D10: =SUM(H10+F10+E10-Z10,"0") -> 4656.88 | E10: =_xlfn.XLOOKUP($A10,Sales!$A:$A,Sales!$G:$G,"0") -> 201.65 | F10: =_xlfn.XLOOKUP($A10,Sales!$A:$A,Sales!$F:$F,"0") -> 0 | G10: =_xlfn.XLOOKUP($A10,Sales!$A:$A,Sales!$AP:$AP,"0") -> 28.2 | H10: =_xlfn.XLOOKUP($A10,Sales!$A:$A,Sales!$C:$C,"0") -> 4455.23 | I10: =C10 -> 389.13 | J10: =_xlfn.XLOOKUP($A10,Sales!$A:$A,Sales!$J:$J,"0") -> 0 | K10: =_xlfn.XLOOKUP($A10,Sales!$A:$A,Sales!$H:$H,"0") -> 0 | L10: 0 | M10: =_xlfn.XLOOKUP($A10,Sales!$A:$A,Sales!$AP:$AP,"0") -> 28.2 | N10: =H10+I10+J10+M10+L10-K10 -> 4872.56 | O10: =_xlfn.XLOOKUP($A10,Sales!$A:$A,Sales!$L:$L,"0") -> 764.83 | P10: =_xlfn.XLOOKUP($A10,Sales!$A:$A,Sales!$M:$M,"0") -> 2864.73 | Q10: =_xlfn.XLOOKUP($A10,Sales!$A:$A,Sales!$N:$N,"0") -> 38.95 | R10: =_xlfn.XLOOKUP($A10,Sales!$A:$A,Sales!$O:$O,"0") -> 186.03 | S10: =_xlfn.XLOOKUP($A10,Sales!$A:$A,Sales!$P:$P,"0") -> 0 | U10: =SUMIFS('EBT AMOUNTS'!I:I,'EBT AMOUNTS'!L:L,Conciliation!A10) -> 7.58 | V10: =_xlfn.XLOOKUP($A10,Sales!$A:$A,Sales!$I:$I,"0")*-1 -> 36.6 | W10: =_xlfn.XLOOKUP($A10,Sales!$A:$A,Sales!$Z:$Z,"0")-K10-U10 -> 886.57 | X10: {=_xlfn.XLOOKUP($A10,Sales!$A:$A,Sales!$T:$T+Sales!$U:$U+Sales!$V:$V,"0")-K10} -> 893 | Y10: =_xlfn.XLOOKUP($A10,Sales!$A:$A,Sales!$AJ:$AJ,"0") -> 0 | Z10: =_xlfn.XLOOKUP($A10,Sales!$A:$A,Sales!$AL:$AL,"0") -> 0 | AA10: =_xlfn.XLOOKUP($A10,Sales!$A:$A,Sales!$AO:$AO,"0") -> 87.27 | AB10: =O10+P10+Q10+S10 -> 3668.51 | AC10: =O10+P10+Q10+R10+S10+V10+W10+Y10+Z10+AA10+U10 -> 4872.56 | AD10: =N10-AC10 -> 0 | AE10: =_xlfn.XLOOKUP($A10,Sales!$A:$A,Sales!$Q:$Q,"0") -> -1.15 | AG10: 30491 | AH10: =VLOOKUP(AG10,Sales!A:V,20,FALSE) -> 893 | AI10: =VLOOKUP(AG10,Sales!A:U,21,FALSE) -> 0 | AJ10: =VLOOKUP(AG10,Sales!A:V,22,FALSE) -> 0 | AK10: =VLOOKUP(AG10,Sales!A:Q,17,FALSE) -> -1.15 | AL10: =SUMIF(A:A,AG10,W:W) -> 886.57 | AM10: =AL10-(AH10+AI10+AJ10)+AK10+U10 -> -6.3948846e-14
A11: 32680 | C11: =_xlfn.XLOOKUP($A11,Sales!$A:$A,Sales!$D:$D,"0") -> 418.82 | D11: =SUM(H11+F11+E11-Z11,"0") -> 5279.46 | E11: =_xlfn.XLOOKUP($A11,Sales!$A:$A,Sales!$G:$G,"0") -> 199.74 | F11: =_xlfn.XLOOKUP($A11,Sales!$A:$A,Sales!$F:$F,"0") -> 3.69 | G11: =_xlfn.XLOOKUP($A11,Sales!$A:$A,Sales!$AP:$AP,"0") -> 25.52 | H11: =_xlfn.XLOOKUP($A11,Sales!$A:$A,Sales!$C:$C,"0") -> 5087.01 | I11: =C11 -> 418.82 | J11: =_xlfn.XLOOKUP($A11,Sales!$A:$A,Sales!$J:$J,"0") -> 0 | K11: =_xlfn.XLOOKUP($A11,Sales!$A:$A,Sales!$H:$H,"0") -> 0 | L11: 0 | M11: =_xlfn.XLOOKUP($A11,Sales!$A:$A,Sales!$AP:$AP,"0") -> 25.52 | N11: =H11+I11+J11+M11+L11-K11 -> 5531.35 | O11: =_xlfn.XLOOKUP($A11,Sales!$A:$A,Sales!$L:$L,"0") -> 434.24 | P11: =_xlfn.XLOOKUP($A11,Sales!$A:$A,Sales!$M:$M,"0") -> 3142.82 | Q11: =_xlfn.XLOOKUP($A11,Sales!$A:$A,Sales!$N:$N,"0") -> 81.92 | R11: =_xlfn.XLOOKUP($A11,Sales!$A:$A,Sales!$O:$O,"0") -> 9.3 | S11: =_xlfn.XLOOKUP($A11,Sales!$A:$A,Sales!$P:$P,"0") -> 0 | V11: =_xlfn.XLOOKUP($A11,Sales!$A:$A,Sales!$I:$I,"0")*-1 -> 0 | W11: =_xlfn.XLOOKUP($A11,Sales!$A:$A,Sales!$Z:$Z,"0")-K11-U11 -> 1433.88 | X11: {=_xlfn.XLOOKUP($A11,Sales!$A:$A,Sales!$T:$T+Sales!$U:$U+Sales!$V:$V,"0")-K11} -> 1432 | Y11: =_xlfn.XLOOKUP($A11,Sales!$A:$A,Sales!$AJ:$AJ,"0") -> 0 | Z11: =_xlfn.XLOOKUP($A11,Sales!$A:$A,Sales!$AL:$AL,"0") -> 10.98 | AA11: =_xlfn.XLOOKUP($A11,Sales!$A:$A,Sales!$AO:$AO,"0") -> 418.21 | AB11: =O11+P11+Q11+S11 -> 3658.98 | AC11: =O11+P11+Q11+R11+S11+V11+W11+Y11+Z11+AA11+U11 -> 5531.35 | AD11: =N11-AC11 -> 0 | AE11: =_xlfn.XLOOKUP($A11,Sales!$A:$A,Sales!$Q:$Q,"0") -> -1.88 | AG11: 32680 | AH11: =VLOOKUP(AG11,Sales!A:V,20,FALSE) -> 1432 | AI11: =VLOOKUP(AG11,Sales!A:U,21,FALSE) -> 0 | AJ11: =VLOOKUP(AG11,Sales!A:V,22,FALSE) -> 0 | AK11: =VLOOKUP(AG11,Sales!A:Q,17,FALSE) -> -1.88 | AL11: =SUMIF(A:A,AG11,W:W) -> 1433.88 | AM11: =AL11-(AH11+AI11+AJ11)+AK11 -> 1.0924595e-13
A12: 32932 | C12: =_xlfn.XLOOKUP($A12,Sales!$A:$A,Sales!$D:$D,"0") -> 0 | D12: =SUM(H12+F12+E12-Z12,"0") -> 6625.5 | E12: =_xlfn.XLOOKUP($A12,Sales!$A:$A,Sales!$G:$G,"0") -> 280.58 | F12: =_xlfn.XLOOKUP($A12,Sales!$A:$A,Sales!$F:$F,"0") -> 9.75 | G12: =_xlfn.XLOOKUP($A12,Sales!$A:$A,Sales!$AP:$AP,"0") -> 16.58 | H12: =_xlfn.XLOOKUP($A12,Sales!$A:$A,Sales!$C:$C,"0") -> 6924.33 | I12: =C12 -> 0 | J12: =_xlfn.XLOOKUP($A12,Sales!$A:$A,Sales!$J:$J,"0") -> 0 | K12: =_xlfn.XLOOKUP($A12,Sales!$A:$A,Sales!$H:$H,"0") -> 0 | L12: 0 | M12: =_xlfn.XLOOKUP($A12,Sales!$A:$A,Sales!$AP:$AP,"0") -> 16.58 | N12: =H12+I12+J12+M12+L12-K12 -> 6940.91 | O12: =_xlfn.XLOOKUP($A12,Sales!$A:$A,Sales!$L:$L,"0") -> 409.76 | P12: =_xlfn.XLOOKUP($A12,Sales!$A:$A,Sales!$M:$M,"0") -> 3736.92 | Q12: =_xlfn.XLOOKUP($A12,Sales!$A:$A,Sales!$N:$N,"0") -> 81.99 | R12: =_xlfn.XLOOKUP($A12,Sales!$A:$A,Sales!$O:$O,"0") -> 27.46 | S12: =_xlfn.XLOOKUP($A12,Sales!$A:$A,Sales!$P:$P,"0") -> 0 | V12: =_xlfn.XLOOKUP($A12,Sales!$A:$A,Sales!$I:$I,"0")*-1 -> 31.19 | W12: =_xlfn.XLOOKUP($A12,Sales!$A:$A,Sales!$Z:$Z,"0")-K12-U12 -> 1254.2 | X12: {=_xlfn.XLOOKUP($A12,Sales!$A:$A,Sales!$T:$T+Sales!$U:$U+Sales!$V:$V,"0")-K12} -> 1260 | Y12: =_xlfn.XLOOKUP($A12,Sales!$A:$A,Sales!$AJ:$AJ,"0") -> 83.22 | Z12: =_xlfn.XLOOKUP($A12,Sales!$A:$A,Sales!$AL:$AL,"0") -> 589.16 | AA12: =_xlfn.XLOOKUP($A12,Sales!$A:$A,Sales!$AO:$AO,"0") -> 727.01 | AB12: =O12+P12+Q12+S12 -> 4228.67 | AC12: =O12+P12+Q12+R12+S12+V12+W12+Y12+Z12+AA12+U12 -> 6940.91 | AD12: =N12-AC12 -> 0 | AE12: =_xlfn.XLOOKUP($A12,Sales!$A:$A,Sales!$Q:$Q,"0") -> 5.8 | AG12: 32932 | AH12: =VLOOKUP(AG12,Sales!A:V,20,FALSE) -> 1260 | AI12: =VLOOKUP(AG12,Sales!A:U,21,FALSE) -> 0 | AJ12: =VLOOKUP(AG12,Sales!A:V,22,FALSE) -> 0 | AK12: =VLOOKUP(AG12,Sales!A:Q,17,FALSE) -> 5.8 | AL12: =SUMIF(A:A,AG12,W:W) -> 1254.2 | AM12: =AL12-(AH12+AI12+AJ12)+AK12 -> 4.5297099e-14
A13: 32933 | C13: =_xlfn.XLOOKUP($A13,Sales!$A:$A,Sales!$D:$D,"0") -> 0 | D13: =SUM(H13+F13+E13-Z13,"0") -> 11276.94 | E13: =_xlfn.XLOOKUP($A13,Sales!$A:$A,Sales!$G:$G,"0") -> 451.4 | F13: =_xlfn.XLOOKUP($A13,Sales!$A:$A,Sales!$F:$F,"0") -> 129.18 | G13: =_xlfn.XLOOKUP($A13,Sales!$A:$A,Sales!$AP:$AP,"0") -> 29.87 | H13: =_xlfn.XLOOKUP($A13,Sales!$A:$A,Sales!$C:$C,"0") -> 12023.19 | I13: =C13 -> 0 | J13: =_xlfn.XLOOKUP($A13,Sales!$A:$A,Sales!$J:$J,"0") -> 20 | K13: =_xlfn.XLOOKUP($A13,Sales!$A:$A,Sales!$H:$H,"0") -> 0 | L13: 0 | M13: =_xlfn.XLOOKUP($A13,Sales!$A:$A,Sales!$AP:$AP,"0") -> 29.87 | N13: =H13+I13+J13+M13+L13-K13 -> 12073.06 | O13: =_xlfn.XLOOKUP($A13,Sales!$A:$A,Sales!$L:$L,"0") -> 865.27 | P13: =_xlfn.XLOOKUP($A13,Sales!$A:$A,Sales!$M:$M,"0") -> 6312.3 | Q13: =_xlfn.XLOOKUP($A13,Sales!$A:$A,Sales!$N:$N,"0") -> 185.85 | R13: =_xlfn.XLOOKUP($A13,Sales!$A:$A,Sales!$O:$O,"0") -> 89.84 | S13: =_xlfn.XLOOKUP($A13,Sales!$A:$A,Sales!$P:$P,"0") -> 0 | V13: =_xlfn.XLOOKUP($A13,Sales!$A:$A,Sales!$I:$I,"0")*-1 -> 59.44 | W13: =_xlfn.XLOOKUP($A13,Sales!$A:$A,Sales!$Z:$Z,"0")-K13-U13 -> 1917.89 | X13: {=_xlfn.XLOOKUP($A13,Sales!$A:$A,Sales!$T:$T+Sales!$U:$U+Sales!$V:$V,"0")-K13} -> 0 | Y13: =_xlfn.XLOOKUP($A13,Sales!$A:$A,Sales!$AJ:$AJ,"0") -> 138.33 | Z13: =_xlfn.XLOOKUP($A13,Sales!$A:$A,Sales!$AL:$AL,"0") -> 1326.83 | AA13: =_xlfn.XLOOKUP($A13,Sales!$A:$A,Sales!$AO:$AO,"0") -> 1177.31 | AB13: =O13+P13+Q13+S13 -> 7363.42 | AC13: =O13+P13+Q13+R13+S13+V13+W13+Y13+Z13+AA13+U13 -> 12073.06 | AD13: =N13-AC13 -> 0 | AE13: =_xlfn.XLOOKUP($A13,Sales!$A:$A,Sales!$Q:$Q,"0") -> -1917.89 | AG13: 32933 | AH13: =VLOOKUP(AG13,Sales!A:V,20,FALSE) -> 0 | AI13: =VLOOKUP(AG13,Sales!A:U,21,FALSE) -> 0 | AJ13: =VLOOKUP(AG13,Sales!A:V,22,FALSE) -> 0 | AK13: =VLOOKUP(AG13,Sales!A:Q,17,FALSE) -> -1917.89 | AL13: =SUMIF(A:A,AG13,W:W) -> 1917.89 | AM13: =AL13-(AH13+AI13+AJ13)+AK13 -> 0
A14: 32934 | C14: =_xlfn.XLOOKUP($A14,Sales!$A:$A,Sales!$D:$D,"0") -> 0 | D14: =SUM(H14+F14+E14-Z14,"0") -> 8336.89 | E14: =_xlfn.XLOOKUP($A14,Sales!$A:$A,Sales!$G:$G,"0") -> 221.92 | F14: =_xlfn.XLOOKUP($A14,Sales!$A:$A,Sales!$F:$F,"0") -> 7.38 | G14: =_xlfn.XLOOKUP($A14,Sales!$A:$A,Sales!$AP:$AP,"0") -> 19.22 | H14: =_xlfn.XLOOKUP($A14,Sales!$A:$A,Sales!$C:$C,"0") -> 8711.2 | I14: =C14 -> 0 | J14: =_xlfn.XLOOKUP($A14,Sales!$A:$A,Sales!$J:$J,"0") -> 0 | K14: =_xlfn.XLOOKUP($A14,Sales!$A:$A,Sales!$H:$H,"0") -> 0 | L14: 0 | M14: =_xlfn.XLOOKUP($A14,Sales!$A:$A,Sales!$AP:$AP,"0") -> 19.22 | N14: =H14+I14+J14+M14+L14-K14 -> 8730.42 | O14: =_xlfn.XLOOKUP($A14,Sales!$A:$A,Sales!$L:$L,"0") -> 973.91 | P14: =_xlfn.XLOOKUP($A14,Sales!$A:$A,Sales!$M:$M,"0") -> 4526.47 | Q14: =_xlfn.XLOOKUP($A14,Sales!$A:$A,Sales!$N:$N,"0") -> 85.01 | R14: =_xlfn.XLOOKUP($A14,Sales!$A:$A,Sales!$O:$O,"0") -> 151.79 | S14: =_xlfn.XLOOKUP($A14,Sales!$A:$A,Sales!$P:$P,"0") -> 0 | V14: =_xlfn.XLOOKUP($A14,Sales!$A:$A,Sales!$I:$I,"0")*-1 -> 15.79 | W14: =_xlfn.XLOOKUP($A14,Sales!$A:$A,Sales!$Z:$Z,"0")-K14-U14 -> 1336.98 | X14: {=_xlfn.XLOOKUP($A14,Sales!$A:$A,Sales!$T:$T+Sales!$U:$U+Sales!$V:$V,"0")-K14} -> 1336 | Y14: =_xlfn.XLOOKUP($A14,Sales!$A:$A,Sales!$AJ:$AJ,"0") -> 182.75 | Z14: =_xlfn.XLOOKUP($A14,Sales!$A:$A,Sales!$AL:$AL,"0") -> 603.61 | AA14: =_xlfn.XLOOKUP($A14,Sales!$A:$A,Sales!$AO:$AO,"0") -> 854.11 | AB14: =O14+P14+Q14+S14 -> 5585.39 | AC14: =O14+P14+Q14+R14+S14+V14+W14+Y14+Z14+AA14+U14 -> 8730.42 | AD14: =N14-AC14 -> 0 | AE14: =_xlfn.XLOOKUP($A14,Sales!$A:$A,Sales!$Q:$Q,"0") -> -0.98 | AG14: 32934 | AH14: =VLOOKUP(AG14,Sales!A:V,20,FALSE) -> 1336 | AI14: =VLOOKUP(AG14,Sales!A:U,21,FALSE) -> 0 | AJ14: =VLOOKUP(AG14,Sales!A:V,22,FALSE) -> 0 | AK14: =VLOOKUP(AG14,Sales!A:Q,17,FALSE) -> -0.98 | AL14: =SUMIF(A:A,AG14,W:W) -> 1336.98 | AM14: =AL14-(AH14+AI14+AJ14)+AK14 -> 1.8207658e-14
A15: 32935 | C15: =_xlfn.XLOOKUP($A15,Sales!$A:$A,Sales!$D:$D,"0") -> 0 | D15: =SUM(H15+F15+E15-Z15,"0") -> 7555.98 | E15: =_xlfn.XLOOKUP($A15,Sales!$A:$A,Sales!$G:$G,"0") -> 503.26 | F15: =_xlfn.XLOOKUP($A15,Sales!$A:$A,Sales!$F:$F,"0") -> 0 | G15: =_xlfn.XLOOKUP($A15,Sales!$A:$A,Sales!$AP:$AP,"0") -> 17.9 | H15: =_xlfn.XLOOKUP($A15,Sales!$A:$A,Sales!$C:$C,"0") -> 7612.57 | I15: =C15 -> 0 | J15: =_xlfn.XLOOKUP($A15,Sales!$A:$A,Sales!$J:$J,"0") -> 0 | K15: =_xlfn.XLOOKUP($A15,Sales!$A:$A,Sales!$H:$H,"0") -> 0 | L15: 0 | M15: =_xlfn.XLOOKUP($A15,Sales!$A:$A,Sales!$AP:$AP,"0") -> 17.9 | N15: =H15+I15+J15+M15+L15-K15 -> 7630.47 | O15: =_xlfn.XLOOKUP($A15,Sales!$A:$A,Sales!$L:$L,"0") -> 482.92 | P15: =_xlfn.XLOOKUP($A15,Sales!$A:$A,Sales!$M:$M,"0") -> 3941.49 | Q15: =_xlfn.XLOOKUP($A15,Sales!$A:$A,Sales!$N:$N,"0") -> 23.08 | R15: =_xlfn.XLOOKUP($A15,Sales!$A:$A,Sales!$O:$O,"0") -> 40.24 | S15: =_xlfn.XLOOKUP($A15,Sales!$A:$A,Sales!$P:$P,"0") -> 0 | V15: =_xlfn.XLOOKUP($A15,Sales!$A:$A,Sales!$I:$I,"0")*-1 -> 0 | W15: =_xlfn.XLOOKUP($A15,Sales!$A:$A,Sales!$Z:$Z,"0")-K15-U15 -> 1358.71 | X15: {=_xlfn.XLOOKUP($A15,Sales!$A:$A,Sales!$T:$T+Sales!$U:$U+Sales!$V:$V,"0")-K15} -> 1353 | Y15: =_xlfn.XLOOKUP($A15,Sales!$A:$A,Sales!$AJ:$AJ,"0") -> 102.16 | Z15: =_xlfn.XLOOKUP($A15,Sales!$A:$A,Sales!$AL:$AL,"0") -> 559.85 | AA15: =_xlfn.XLOOKUP($A15,Sales!$A:$A,Sales!$AO:$AO,"0") -> 1122.02 | AB15: =O15+P15+Q15+S15 -> 4447.49 | AC15: =O15+P15+Q15+R15+S15+V15+W15+Y15+Z15+AA15+U15 -> 7630.47 | AD15: =N15-AC15 -> 0 | AE15: =_xlfn.XLOOKUP($A15,Sales!$A:$A,Sales!$Q:$Q,"0") -> -5.71 | AG15: 32935 | AH15: =VLOOKUP(AG15,Sales!A:V,20,FALSE) -> 1353 | AI15: =VLOOKUP(AG15,Sales!A:U,21,FALSE) -> 0 | AJ15: =VLOOKUP(AG15,Sales!A:V,22,FALSE) -> 0 | AK15: =VLOOKUP(AG15,Sales!A:Q,17,FALSE) -> -5.71 | AL15: =SUMIF(A:A,AG15,W:W) -> 1358.71 | AM15: =AL15-(AH15+AI15+AJ15)+AK15 -> 3.6415315e-14
A16: 32936 | C16: =_xlfn.XLOOKUP($A16,Sales!$A:$A,Sales!$D:$D,"0") -> 0 | D16: =SUM(H16+F16+E16-Z16,"0") -> 7484.98 | E16: =_xlfn.XLOOKUP($A16,Sales!$A:$A,Sales!$G:$G,"0") -> 244.93 | F16: =_xlfn.XLOOKUP($A16,Sales!$A:$A,Sales!$F:$F,"0") -> 50.2 | G16: =_xlfn.XLOOKUP($A16,Sales!$A:$A,Sales!$AP:$AP,"0") -> 4.98 | H16: =_xlfn.XLOOKUP($A16,Sales!$A:$A,Sales!$C:$C,"0") -> 7498.21 | I16: =C16 -> 0 | J16: =_xlfn.XLOOKUP($A16,Sales!$A:$A,Sales!$J:$J,"0") -> 0 | K16: =_xlfn.XLOOKUP($A16,Sales!$A:$A,Sales!$H:$H,"0") -> 0 | L16: 0 | M16: =_xlfn.XLOOKUP($A16,Sales!$A:$A,Sales!$AP:$AP,"0") -> 4.98 | N16: =H16+I16+J16+M16+L16-K16 -> 7503.19 | O16: =_xlfn.XLOOKUP($A16,Sales!$A:$A,Sales!$L:$L,"0") -> 742.5 | P16: =_xlfn.XLOOKUP($A16,Sales!$A:$A,Sales!$M:$M,"0") -> 4390.59 | Q16: =_xlfn.XLOOKUP($A16,Sales!$A:$A,Sales!$N:$N,"0") -> 132.59 | R16: =_xlfn.XLOOKUP($A16,Sales!$A:$A,Sales!$O:$O,"0") -> 136.49 | S16: =_xlfn.XLOOKUP($A16,Sales!$A:$A,Sales!$P:$P,"0") -> 0 | V16: =_xlfn.XLOOKUP($A16,Sales!$A:$A,Sales!$I:$I,"0")*-1 -> 32.51 | W16: =_xlfn.XLOOKUP($A16,Sales!$A:$A,Sales!$Z:$Z,"0")-K16-U16 -> 1209.01 | X16: {=_xlfn.XLOOKUP($A16,Sales!$A:$A,Sales!$T:$T+Sales!$U:$U+Sales!$V:$V,"0")-K16} -> 1208 | Y16: =_xlfn.XLOOKUP($A16,Sales!$A:$A,Sales!$AJ:$AJ,"0") -> 80.1 | Z16: =_xlfn.XLOOKUP($A16,Sales!$A:$A,Sales!$AL:$AL,"0") -> 308.36 | AA16: =_xlfn.XLOOKUP($A16,Sales!$A:$A,Sales!$AO:$AO,"0") -> 471.04 | AB16: =O16+P16+Q16+S16 -> 5265.68 | AC16: =O16+P16+Q16+R16+S16+V16+W16+Y16+Z16+AA16+U16 -> 7503.19 | AD16: =N16-AC16 -> 0 | AE16: =_xlfn.XLOOKUP($A16,Sales!$A:$A,Sales!$Q:$Q,"0") -> -1.01 | AG16: 32936 | AH16: =VLOOKUP(AG16,Sales!A:V,20,FALSE) -> 1208 | AI16: =VLOOKUP(AG16,Sales!A:U,21,FALSE) -> 0 | AJ16: =VLOOKUP(AG16,Sales!A:V,22,FALSE) -> 0 | AK16: =VLOOKUP(AG16,Sales!A:Q,17,FALSE) -> -1.01 | AL16: =SUMIF(A:A,AG16,W:W) -> 1209.01 | AM16: =AL16-(AH16+AI16+AJ16)+AK16 -> -9.1038288e-15
A17: 32937 | C17: =_xlfn.XLOOKUP($A17,Sales!$A:$A,Sales!$D:$D,"0") -> 0 | D17: =SUM(H17+F17+E17-Z17,"0") -> 11481.67 | E17: =_xlfn.XLOOKUP($A17,Sales!$A:$A,Sales!$G:$G,"0") -> 461.68 | F17: =_xlfn.XLOOKUP($A17,Sales!$A:$A,Sales!$F:$F,"0") -> 8.95 | G17: =_xlfn.XLOOKUP($A17,Sales!$A:$A,Sales!$AP:$AP,"0") -> 25.72 | H17: =_xlfn.XLOOKUP($A17,Sales!$A:$A,Sales!$C:$C,"0") -> 12233.19 | I17: =C17 -> 0 | J17: =_xlfn.XLOOKUP($A17,Sales!$A:$A,Sales!$J:$J,"0") -> 0 | K17: =_xlfn.XLOOKUP($A17,Sales!$A:$A,Sales!$H:$H,"0") -> 0 | L17: 0 | M17: =_xlfn.XLOOKUP($A17,Sales!$A:$A,Sales!$AP:$AP,"0") -> 25.72 | N17: =H17+I17+J17+M17+L17-K17 -> 12258.91 | O17: =_xlfn.XLOOKUP($A17,Sales!$A:$A,Sales!$L:$L,"0") -> 867.75 | P17: =_xlfn.XLOOKUP($A17,Sales!$A:$A,Sales!$M:$M,"0") -> 6032.12 | Q17: =_xlfn.XLOOKUP($A17,Sales!$A:$A,Sales!$N:$N,"0") -> 183.35 | R17: =_xlfn.XLOOKUP($A17,Sales!$A:$A,Sales!$O:$O,"0") -> 157.09 | S17: =_xlfn.XLOOKUP($A17,Sales!$A:$A,Sales!$P:$P,"0") -> 0 | V17: =_xlfn.XLOOKUP($A17,Sales!$A:$A,Sales!$I:$I,"0")*-1 -> 28.5 | W17: =_xlfn.XLOOKUP($A17,Sales!$A:$A,Sales!$Z:$Z,"0")-K17-U17 -> 1446.9 | X17: {=_xlfn.XLOOKUP($A17,Sales!$A:$A,Sales!$T:$T+Sales!$U:$U+Sales!$V:$V,"0")-K17} -> 1445 | Y17: =_xlfn.XLOOKUP($A17,Sales!$A:$A,Sales!$AJ:$AJ,"0") -> 304.25 | Z17: =_xlfn.XLOOKUP($A17,Sales!$A:$A,Sales!$AL:$AL,"0") -> 1222.15 | AA17: =_xlfn.XLOOKUP($A17,Sales!$A:$A,Sales!$AO:$AO,"0") -> 2016.8 | AB17: =O17+P17+Q17+S17 -> 7083.22 | AC17: =O17+P17+Q17+R17+S17+V17+W17+Y17+Z17+AA17+U17 -> 12258.91 | AD17: =N17-AC17 -> 0 | AE17: =_xlfn.XLOOKUP($A17,Sales!$A:$A,Sales!$Q:$Q,"0") -> -1.9 | AG17: 32937 | AH17: =VLOOKUP(AG17,Sales!A:V,20,FALSE) -> 1445 | AI17: =VLOOKUP(AG17,Sales!A:U,21,FALSE) -> 0 | AJ17: =VLOOKUP(AG17,Sales!A:V,22,FALSE) -> 0 | AK17: =VLOOKUP(AG17,Sales!A:Q,17,FALSE) -> -1.9 | AL17: =SUMIF(A:A,AG17,W:W) -> 1446.9 | AM17: =AL17-(AH17+AI17+AJ17)+AK17 -> 9.1038288e-14
A18: 32938 | C18: =_xlfn.XLOOKUP($A18,Sales!$A:$A,Sales!$D:$D,"0") -> 0 | D18: =SUM(H18+F18+E18-Z18,"0") -> 7617.67 | E18: =_xlfn.XLOOKUP($A18,Sales!$A:$A,Sales!$G:$G,"0") -> 343.84 | F18: =_xlfn.XLOOKUP($A18,Sales!$A:$A,Sales!$F:$F,"0") -> 91.73 | G18: =_xlfn.XLOOKUP($A18,Sales!$A:$A,Sales!$AP:$AP,"0") -> 16.58 | H18: =_xlfn.XLOOKUP($A18,Sales!$A:$A,Sales!$C:$C,"0") -> 7570.92 | I18: =C18 -> 0 | J18: =_xlfn.XLOOKUP($A18,Sales!$A:$A,Sales!$J:$J,"0") -> 25 | K18: =_xlfn.XLOOKUP($A18,Sales!$A:$A,Sales!$H:$H,"0") -> 0 | L18: 0 | M18: =_xlfn.XLOOKUP($A18,Sales!$A:$A,Sales!$AP:$AP,"0") -> 16.58 | N18: =H18+I18+J18+M18+L18-K18 -> 7612.5 | O18: =_xlfn.XLOOKUP($A18,Sales!$A:$A,Sales!$L:$L,"0") -> 876.63 | P18: =_xlfn.XLOOKUP($A18,Sales!$A:$A,Sales!$M:$M,"0") -> 4367.9 | Q18: =_xlfn.XLOOKUP($A18,Sales!$A:$A,Sales!$N:$N,"0") -> 62.82 | R18: =_xlfn.XLOOKUP($A18,Sales!$A:$A,Sales!$O:$O,"0") -> 71.22 | S18: =_xlfn.XLOOKUP($A18,Sales!$A:$A,Sales!$P:$P,"0") -> 0 | V18: =_xlfn.XLOOKUP($A18,Sales!$A:$A,Sales!$I:$I,"0")*-1 -> 46.62 | W18: =_xlfn.XLOOKUP($A18,Sales!$A:$A,Sales!$Z:$Z,"0")-K18-U18 -> 971.08 | X18: {=_xlfn.XLOOKUP($A18,Sales!$A:$A,Sales!$T:$T+Sales!$U:$U+Sales!$V:$V,"0")-K18} -> 969 | Y18: =_xlfn.XLOOKUP($A18,Sales!$A:$A,Sales!$AJ:$AJ,"0") -> 149.55 | Z18: =_xlfn.XLOOKUP($A18,Sales!$A:$A,Sales!$AL:$AL,"0") -> 388.82 | AA18: =_xlfn.XLOOKUP($A18,Sales!$A:$A,Sales!$AO:$AO,"0") -> 677.86 | AB18: =O18+P18+Q18+S18 -> 5307.35 | AC18: =O18+P18+Q18+R18+S18+V18+W18+Y18+Z18+AA18+U18 -> 7612.5 | AD18: =N18-AC18 -> 0 | AE18: =_xlfn.XLOOKUP($A18,Sales!$A:$A,Sales!$Q:$Q,"0") -> -2.08 | AG18: 32938 | AH18: =VLOOKUP(AG18,Sales!A:V,20,FALSE) -> 969 | AI18: =VLOOKUP(AG18,Sales!A:U,21,FALSE) -> 0 | AJ18: =VLOOKUP(AG18,Sales!A:V,22,FALSE) -> 0 | AK18: =VLOOKUP(AG18,Sales!A:Q,17,FALSE) -> -2.08 | AL18: =SUMIF(A:A,AG18,W:W) -> 971.08 | AM18: =AL18-(AH18+AI18+AJ18)+AK18 -> 4.0856207e-14
A19: 32939 | C19: =_xlfn.XLOOKUP($A19,Sales!$A:$A,Sales!$D:$D,"0") -> 0 | D19: =SUM(H19+F19+E19-Z19,"0") -> 11172.05 | E19: =_xlfn.XLOOKUP($A19,Sales!$A:$A,Sales!$G:$G,"0") -> 336.77 | F19: =_xlfn.XLOOKUP($A19,Sales!$A:$A,Sales!$F:$F,"0") -> 0 | G19: =_xlfn.XLOOKUP($A19,Sales!$A:$A,Sales!$AP:$AP,"0") -> 13.97 | H19: =_xlfn.XLOOKUP($A19,Sales!$A:$A,Sales!$C:$C,"0") -> 11533.5 | I19: =C19 -> 0 | J19: =_xlfn.XLOOKUP($A19,Sales!$A:$A,Sales!$J:$J,"0") -> 0 | K19: =_xlfn.XLOOKUP($A19,Sales!$A:$A,Sales!$H:$H,"0") -> 0 | L19: 0 | M19: =_xlfn.XLOOKUP($A19,Sales!$A:$A,Sales!$AP:$AP,"0") -> 13.97 | N19: =H19+I19+J19+M19+L19-K19 -> 11547.47 | O19: =_xlfn.XLOOKUP($A19,Sales!$A:$A,Sales!$L:$L,"0") -> 1027.46 | P19: =_xlfn.XLOOKUP($A19,Sales!$A:$A,Sales!$M:$M,"0") -> 6966.36 | Q19: =_xlfn.XLOOKUP($A19,Sales!$A:$A,Sales!$N:$N,"0") -> 129.49 | R19: =_xlfn.XLOOKUP($A19,Sales!$A:$A,Sales!$O:$O,"0") -> 87.63 | S19: =_xlfn.XLOOKUP($A19,Sales!$A:$A,Sales!$P:$P,"0") -> 0 | V19: =_xlfn.XLOOKUP($A19,Sales!$A:$A,Sales!$I:$I,"0")*-1 -> 40.25 | W19: =_xlfn.XLOOKUP($A19,Sales!$A:$A,Sales!$Z:$Z,"0")-K19-U19 -> 1365.25 | X19: {=_xlfn.XLOOKUP($A19,Sales!$A:$A,Sales!$T:$T+Sales!$U:$U+Sales!$V:$V,"0")-K19} -> 1368 | Y19: =_xlfn.XLOOKUP($A19,Sales!$A:$A,Sales!$AJ:$AJ,"0") -> 153.34 | Z19: =_xlfn.XLOOKUP($A19,Sales!$A:$A,Sales!$AL:$AL,"0") -> 698.22 | AA19: =_xlfn.XLOOKUP($A19,Sales!$A:$A,Sales!$AO:$AO,"0") -> 1079.47 | AB19: =O19+P19+Q19+S19 -> 8123.31 | AC19: =O19+P19+Q19+R19+S19+V19+W19+Y19+Z19+AA19+U19 -> 11547.47 | AD19: =N19-AC19 -> 0 | AE19: =_xlfn.XLOOKUP($A19,Sales!$A:$A,Sales!$Q:$Q,"0") -> 2.75 | AG19: 32939 | AH19: =VLOOKUP(AG19,Sales!A:V,20,FALSE) -> 1368 | AI19: =VLOOKUP(AG19,Sales!A:U,21,FALSE) -> 0 | AJ19: =VLOOKUP(AG19,Sales!A:V,22,FALSE) -> 0 | AK19: =VLOOKUP(AG19,Sales!A:Q,17,FALSE) -> 2.75 | AL19: =SUMIF(A:A,AG19,W:W) -> 1365.25 | AM19: =AL19-(AH19+AI19+AJ19)+AK19 -> 0
A20: 32940 | C20: =_xlfn.XLOOKUP($A20,Sales!$A:$A,Sales!$D:$D,"0") -> 0 | D20: =SUM(H20+F20+E20-Z20,"0") -> 7206.16 | E20: =_xlfn.XLOOKUP($A20,Sales!$A:$A,Sales!$G:$G,"0") -> 173.57 | F20: =_xlfn.XLOOKUP($A20,Sales!$A:$A,Sales!$F:$F,"0") -> 0 | G20: =_xlfn.XLOOKUP($A20,Sales!$A:$A,Sales!$AP:$AP,"0") -> 10.1 | H20: =_xlfn.XLOOKUP($A20,Sales!$A:$A,Sales!$C:$C,"0") -> 7781.39 | I20: =C20 -> 0 | J20: =_xlfn.XLOOKUP($A20,Sales!$A:$A,Sales!$J:$J,"0") -> 0 | K20: =_xlfn.XLOOKUP($A20,Sales!$A:$A,Sales!$H:$H,"0") -> 0 | L20: 0 | M20: =_xlfn.XLOOKUP($A20,Sales!$A:$A,Sales!$AP:$AP,"0") -> 10.1 | N20: =H20+I20+J20+M20+L20-K20 -> 7791.49 | O20: =_xlfn.XLOOKUP($A20,Sales!$A:$A,Sales!$L:$L,"0") -> 890.14 | P20: =_xlfn.XLOOKUP($A20,Sales!$A:$A,Sales!$M:$M,"0") -> 3547.34 | Q20: =_xlfn.XLOOKUP($A20,Sales!$A:$A,Sales!$N:$N,"0") -> 113.36 | R20: =_xlfn.XLOOKUP($A20,Sales!$A:$A,Sales!$O:$O,"0") -> 120.32 | S20: =_xlfn.XLOOKUP($A20,Sales!$A:$A,Sales!$P:$P,"0") -> 0 | V20: =_xlfn.XLOOKUP($A20,Sales!$A:$A,Sales!$I:$I,"0")*-1 -> 18.55 | W20: =_xlfn.XLOOKUP($A20,Sales!$A:$A,Sales!$Z:$Z,"0")-K20-U20 -> 913.37 | X20: {=_xlfn.XLOOKUP($A20,Sales!$A:$A,Sales!$T:$T+Sales!$U:$U+Sales!$V:$V,"0")-K20} -> 916 | Y20: =_xlfn.XLOOKUP($A20,Sales!$A:$A,Sales!$AJ:$AJ,"0") -> 317 | Z20: =_xlfn.XLOOKUP($A20,Sales!$A:$A,Sales!$AL:$AL,"0") -> 748.8 | AA20: =_xlfn.XLOOKUP($A20,Sales!$A:$A,Sales!$AO:$AO,"0") -> 1122.61 | AB20: =O20+P20+Q20+S20 -> 4550.84 | AC20: =O20+P20+Q20+R20+S20+V20+W20+Y20+Z20+AA20+U20 -> 7791.49 | AD20: =N20-AC20 -> 0 | AE20: =_xlfn.XLOOKUP($A20,Sales!$A:$A,Sales!$Q:$Q,"0") -> 2.63 | AG20: 32940 | AH20: =VLOOKUP(AG20,Sales!A:V,20,FALSE) -> 916 | AI20: =VLOOKUP(AG20,Sales!A:U,21,FALSE) -> 0 | AJ20: =VLOOKUP(AG20,Sales!A:V,22,FALSE) -> 0 | AK20: =VLOOKUP(AG20,Sales!A:Q,17,FALSE) -> 2.63 | AL20: =SUMIF(A:A,AG20,W:W) -> 913.37 | AM20: =AL20-(AH20+AI20+AJ20)+AK20 -> 4.4408921e-15
A21: 32941 | C21: =_xlfn.XLOOKUP($A21,Sales!$A:$A,Sales!$D:$D,"0") -> 0 | D21: =SUM(H21+F21+E21-Z21,"0") -> 6688.42 | E21: =_xlfn.XLOOKUP($A21,Sales!$A:$A,Sales!$G:$G,"0") -> 197.08 | F21: =_xlfn.XLOOKUP($A21,Sales!$A:$A,Sales!$F:$F,"0") -> 23.33 | G21: =_xlfn.XLOOKUP($A21,Sales!$A:$A,Sales!$AP:$AP,"0") -> 1.81 | H21: =_xlfn.XLOOKUP($A21,Sales!$A:$A,Sales!$C:$C,"0") -> 7246.22 | I21: =C21 -> 0 | J21: =_xlfn.XLOOKUP($A21,Sales!$A:$A,Sales!$J:$J,"0") -> 0 | K21: =_xlfn.XLOOKUP($A21,Sales!$A:$A,Sales!$H:$H,"0") -> 0 | L21: 0 | M21: =_xlfn.XLOOKUP($A21,Sales!$A:$A,Sales!$AP:$AP,"0") -> 1.81 | N21: =H21+I21+J21+M21+L21-K21 -> 7248.03 | O21: =_xlfn.XLOOKUP($A21,Sales!$A:$A,Sales!$L:$L,"0") -> 598.19 | P21: =_xlfn.XLOOKUP($A21,Sales!$A:$A,Sales!$M:$M,"0") -> 3722.19 | Q21: =_xlfn.XLOOKUP($A21,Sales!$A:$A,Sales!$N:$N,"0") -> 70.77 | R21: =_xlfn.XLOOKUP($A21,Sales!$A:$A,Sales!$O:$O,"0") -> 77.66 | S21: =_xlfn.XLOOKUP($A21,Sales!$A:$A,Sales!$P:$P,"0") -> 0 | V21: =_xlfn.XLOOKUP($A21,Sales!$A:$A,Sales!$I:$I,"0")*-1 -> 0 | W21: =_xlfn.XLOOKUP($A21,Sales!$A:$A,Sales!$Z:$Z,"0")-K21-U21 -> 920 | X21: {=_xlfn.XLOOKUP($A21,Sales!$A:$A,Sales!$T:$T+Sales!$U:$U+Sales!$V:$V,"0")-K21} -> 885 | Y21: =_xlfn.XLOOKUP($A21,Sales!$A:$A,Sales!$AJ:$AJ,"0") -> 176.61 | Z21: =_xlfn.XLOOKUP($A21,Sales!$A:$A,Sales!$AL:$AL,"0") -> 778.21 | AA21: =_xlfn.XLOOKUP($A21,Sales!$A:$A,Sales!$AO:$AO,"0") -> 904.4 | AB21: =O21+P21+Q21+S21 -> 4391.15 | AC21: =O21+P21+Q21+R21+S21+V21+W21+Y21+Z21+AA21+U21 -> 7248.03 | AD21: =N21-AC21 -> 0 | AE21: =_xlfn.XLOOKUP($A21,Sales!$A:$A,Sales!$Q:$Q,"0") -> -35 | AG21: 32941 | AH21: =VLOOKUP(AG21,Sales!A:V,20,FALSE) -> 885 | AI21: =VLOOKUP(AG21,Sales!A:U,21,FALSE) -> 0 | AJ21: =VLOOKUP(AG21,Sales!A:V,22,FALSE) -> 0 | AK21: =VLOOKUP(AG21,Sales!A:Q,17,FALSE) -> -35 | AL21: =SUMIF(A:A,AG21,W:W) -> 920 | AM21: =AL21-(AH21+AI21+AJ21)+AK21 -> 0
A22: 32942 | C22: =_xlfn.XLOOKUP($A22,Sales!$A:$A,Sales!$D:$D,"0") -> 0 | D22: =SUM(H22+F22+E22-Z22,"0") -> 7918.03 | E22: =_xlfn.XLOOKUP($A22,Sales!$A:$A,Sales!$G:$G,"0") -> 353.55 | F22: =_xlfn.XLOOKUP($A22,Sales!$A:$A,Sales!$F:$F,"0") -> 3.19 | G22: =_xlfn.XLOOKUP($A22,Sales!$A:$A,Sales!$AP:$AP,"0") -> 28.63 | H22: =_xlfn.XLOOKUP($A22,Sales!$A:$A,Sales!$C:$C,"0") -> 7745.13 | I22: =C22 -> 0 | J22: =_xlfn.XLOOKUP($A22,Sales!$A:$A,Sales!$J:$J,"0") -> 0 | K22: =_xlfn.XLOOKUP($A22,Sales!$A:$A,Sales!$H:$H,"0") -> 0 | L22: 0 | M22: =_xlfn.XLOOKUP($A22,Sales!$A:$A,Sales!$AP:$AP,"0") -> 28.63 | N22: =H22+I22+J22+M22+L22-K22 -> 7773.76 | O22: =_xlfn.XLOOKUP($A22,Sales!$A:$A,Sales!$L:$L,"0") -> 812.54 | P22: =_xlfn.XLOOKUP($A22,Sales!$A:$A,Sales!$M:$M,"0") -> 4526.93 | Q22: =_xlfn.XLOOKUP($A22,Sales!$A:$A,Sales!$N:$N,"0") -> 143.34 | R22: =_xlfn.XLOOKUP($A22,Sales!$A:$A,Sales!$O:$O,"0") -> 112.46 | S22: =_xlfn.XLOOKUP($A22,Sales!$A:$A,Sales!$P:$P,"0") -> 0 | V22: =_xlfn.XLOOKUP($A22,Sales!$A:$A,Sales!$I:$I,"0")*-1 -> 52.19 | W22: =_xlfn.XLOOKUP($A22,Sales!$A:$A,Sales!$Z:$Z,"0")-K22-U22 -> 1250.11 | X22: {=_xlfn.XLOOKUP($A22,Sales!$A:$A,Sales!$T:$T+Sales!$U:$U+Sales!$V:$V,"0")-K22} -> 1248 | Y22: =_xlfn.XLOOKUP($A22,Sales!$A:$A,Sales!$AJ:$AJ,"0") -> 114.83 | Z22: =_xlfn.XLOOKUP($A22,Sales!$A:$A,Sales!$AL:$AL,"0") -> 183.84 | AA22: =_xlfn.XLOOKUP($A22,Sales!$A:$A,Sales!$AO:$AO,"0") -> 577.52 | AB22: =O22+P22+Q22+S22 -> 5482.81 | AC22: =O22+P22+Q22+R22+S22+V22+W22+Y22+Z22+AA22+U22 -> 7773.76 | AD22: =N22-AC22 -> 0 | AE22: =_xlfn.XLOOKUP($A22,Sales!$A:$A,Sales!$Q:$Q,"0") -> -2.11 | AG22: 32942 | AH22: =VLOOKUP(AG22,Sales!A:V,20,FALSE) -> 1248 | AI22: =VLOOKUP(AG22,Sales!A:U,21,FALSE) -> 0 | AJ22: =VLOOKUP(AG22,Sales!A:V,22,FALSE) -> 0 | AK22: =VLOOKUP(AG22,Sales!A:Q,17,FALSE) -> -2.11 | AL22: =SUMIF(A:A,AG22,W:W) -> 1250.11 | AM22: =AL22-(AH22+AI22+AJ22)+AK22 -> -9.9920072e-14
... A33: 34793 | C33: =_xlfn.XLOOKUP($A33,Sales!$A:$A,Sales!$D:$D,"0") -> 382.34 | D33: =SUM(H33+F33+E33-Z33,"0") -> 4396.7 | E33: =_xlfn.XLOOKUP($A33,Sales!$A:$A,Sales!$G:$G,"0") -> 133.87 | F33: =_xlfn.XLOOKUP($A33,Sales!$A:$A,Sales!$F:$F,"0") -> 3.19 | G33: =_xlfn.XLOOKUP($A33,Sales!$A:$A,Sales!$AP:$AP,"0") -> 29.34 | H33: =_xlfn.XLOOKUP($A33,Sales!$A:$A,Sales!$C:$C,"0") -> 4329.39 | I33: =C33 -> 382.34 | J33: =_xlfn.XLOOKUP($A33,Sales!$A:$A,Sales!$J:$J,"0") -> 15 | K33: =_xlfn.XLOOKUP($A33,Sales!$A:$A,Sales!$H:$H,"0") -> 0 | L33: 0 | M33: =_xlfn.XLOOKUP($A33,Sales!$A:$A,Sales!$AP:$AP,"0") -> 29.34 | N33: =H33+I33+J33+M33+L33-K33 -> 4756.07 | O33: =_xlfn.XLOOKUP($A33,Sales!$A:$A,Sales!$L:$L,"0") -> 466.51 | P33: =_xlfn.XLOOKUP($A33,Sales!$A:$A,Sales!$M:$M,"0") -> 3096.72 | Q33: =_xlfn.XLOOKUP($A33,Sales!$A:$A,Sales!$N:$N,"0") -> 85.72 | R33: =_xlfn.XLOOKUP($A33,Sales!$A:$A,Sales!$O:$O,"0") -> 76.05 | S33: =_xlfn.XLOOKUP($A33,Sales!$A:$A,Sales!$P:$P,"0") -> 0 | V33: =_xlfn.XLOOKUP($A33,Sales!$A:$A,Sales!$I:$I,"0")*-1 -> 14.66 | W33: =_xlfn.XLOOKUP($A33,Sales!$A:$A,Sales!$Z:$Z,"0")-K33-U33 -> 897.71 | X33: {=_xlfn.XLOOKUP($A33,Sales!$A:$A,Sales!$T:$T+Sales!$U:$U+Sales!$V:$V,"0")-K33} -> 896 | Y33: =_xlfn.XLOOKUP($A33,Sales!$A:$A,Sales!$AJ:$AJ,"0") -> 0 | Z33: =_xlfn.XLOOKUP($A33,Sales!$A:$A,Sales!$AL:$AL,"0") -> 69.75 | AA33: =_xlfn.XLOOKUP($A33,Sales!$A:$A,Sales!$AO:$AO,"0") -> 48.95 | AB33: =O33+P33+Q33+S33 -> 3648.95 | AC33: =O33+P33+Q33+R33+S33+V33+W33+Y33+Z33+AA33+U33 -> 4756.07 | AD33: =N33-AC33 -> 0 | AE33: =_xlfn.XLOOKUP($A33,Sales!$A:$A,Sales!$Q:$Q,"0") -> -1.71 | AG33: 34793 | AH33: =VLOOKUP(AG33,Sales!A:V,20,FALSE) -> 896 | AI33: =VLOOKUP(AG33,Sales!A:U,21,FALSE) -> 0 | AJ33: =VLOOKUP(AG33,Sales!A:V,22,FALSE) -> 0 | AK33: =VLOOKUP(AG33,Sales!A:Q,17,FALSE) -> -1.71 | AL33: =SUMIF(A:A,AG33,W:W) -> 897.71 | AM33: =AL33-(AH33+AI33+AJ33)+AK33 -> 3.6415315e-14
A34: 36224 | C34: =_xlfn.XLOOKUP($A34,Sales!$A:$A,Sales!$D:$D,"0") -> 410.72 | D34: =SUM(H34+F34+E34-Z34,"0") -> 5217.4 | E34: =_xlfn.XLOOKUP($A34,Sales!$A:$A,Sales!$G:$G,"0") -> 142.86 | F34: =_xlfn.XLOOKUP($A34,Sales!$A:$A,Sales!$F:$F,"0") -> 0 | G34: =_xlfn.XLOOKUP($A34,Sales!$A:$A,Sales!$AP:$AP,"0") -> 8.86 | H34: =_xlfn.XLOOKUP($A34,Sales!$A:$A,Sales!$C:$C,"0") -> 5130.87 | I34: =C34 -> 410.72 | J34: =_xlfn.XLOOKUP($A34,Sales!$A:$A,Sales!$J:$J,"0") -> 10 | K34: =_xlfn.XLOOKUP($A34,Sales!$A:$A,Sales!$H:$H,"0") -> 0 | L34: 0 | M34: =_xlfn.XLOOKUP($A34,Sales!$A:$A,Sales!$AP:$AP,"0") -> 8.86 | N34: =H34+I34+J34+M34+L34-K34 -> 5560.45 | O34: =_xlfn.XLOOKUP($A34,Sales!$A:$A,Sales!$L:$L,"0") -> 590.68 | P34: =_xlfn.XLOOKUP($A34,Sales!$A:$A,Sales!$M:$M,"0") -> 3467.34 | Q34: =_xlfn.XLOOKUP($A34,Sales!$A:$A,Sales!$N:$N,"0") -> 56.43 | R34: =_xlfn.XLOOKUP($A34,Sales!$A:$A,Sales!$O:$O,"0") -> 70.05 | S34: =_xlfn.XLOOKUP($A34,Sales!$A:$A,Sales!$P:$P,"0") -> 0 | U34: =SUMIFS('EBT AMOUNTS'!I:I,'EBT AMOUNTS'!L:L,Conciliation!A34) -> 20.15 | V34: =_xlfn.XLOOKUP($A34,Sales!$A:$A,Sales!$I:$I,"0")*-1 -> 16.12 | W34: =_xlfn.XLOOKUP($A34,Sales!$A:$A,Sales!$Z:$Z,"0")-K34-U34 -> 667.31 | X34: {=_xlfn.XLOOKUP($A34,Sales!$A:$A,Sales!$T:$T+Sales!$U:$U+Sales!$V:$V,"0")-K34} -> 648.61 | Y34: =_xlfn.XLOOKUP($A34,Sales!$A:$A,Sales!$AJ:$AJ,"0") -> 50.37 | Z34: =_xlfn.XLOOKUP($A34,Sales!$A:$A,Sales!$AL:$AL,"0") -> 56.33 | AA34: =_xlfn.XLOOKUP($A34,Sales!$A:$A,Sales!$AO:$AO,"0") -> 565.67 | AB34: =O34+P34+Q34+S34 -> 4114.45 | AC34: =O34+P34+Q34+R34+S34+V34+W34+Y34+Z34+AA34+U34 -> 5560.45 | AD34: =N34-AC34 -> 0 | AE34: =_xlfn.XLOOKUP($A34,Sales!$A:$A,Sales!$Q:$Q,"0") -> -38.85 | AG34: 36224 | AH34: =VLOOKUP(AG34,Sales!A:V,20,FALSE) -> 648.61 | AI34: =VLOOKUP(AG34,Sales!A:U,21,FALSE) -> 0 | AJ34: =VLOOKUP(AG34,Sales!A:V,22,FALSE) -> 0 | AK34: =VLOOKUP(AG34,Sales!A:Q,17,FALSE) -> -38.85 | AL34: =SUMIF(A:A,AG34,W:W) -> 667.31 | AM34: =AL34-(AH34+AI34+AJ34)+AK34+U34 -> 4.2632564e-14
A35: 36225 | C35: =_xlfn.XLOOKUP($A35,Sales!$A:$A,Sales!$D:$D,"0") -> 0 | D35: =SUM(H35+F35+E35-Z35,"0") -> 0 | E35: =_xlfn.XLOOKUP($A35,Sales!$A:$A,Sales!$G:$G,"0") -> 0 | F35: =_xlfn.XLOOKUP($A35,Sales!$A:$A,Sales!$F:$F,"0") -> 0 | G35: =_xlfn.XLOOKUP($A35,Sales!$A:$A,Sales!$AP:$AP,"0") -> 0 | H35: =_xlfn.XLOOKUP($A35,Sales!$A:$A,Sales!$C:$C,"0") -> 0 | I35: =C35 -> 0 | J35: =_xlfn.XLOOKUP($A35,Sales!$A:$A,Sales!$J:$J,"0") -> 0 | K35: =_xlfn.XLOOKUP($A35,Sales!$A:$A,Sales!$H:$H,"0") -> 0 | L35: 0 | M35: =_xlfn.XLOOKUP($A35,Sales!$A:$A,Sales!$AP:$AP,"0") -> 0 | N35: =H35+I35+J35+M35+L35-K35 -> 0 | O35: =_xlfn.XLOOKUP($A35,Sales!$A:$A,Sales!$L:$L,"0") -> 0 | P35: =_xlfn.XLOOKUP($A35,Sales!$A:$A,Sales!$M:$M,"0") -> 0 | Q35: =_xlfn.XLOOKUP($A35,Sales!$A:$A,Sales!$N:$N,"0") -> 0 | R35: =_xlfn.XLOOKUP($A35,Sales!$A:$A,Sales!$O:$O,"0") -> 0 | S35: =_xlfn.XLOOKUP($A35,Sales!$A:$A,Sales!$P:$P,"0") -> 0 | V35: =_xlfn.XLOOKUP($A35,Sales!$A:$A,Sales!$I:$I,"0")*-1 -> 0 | W35: =_xlfn.XLOOKUP($A35,Sales!$A:$A,Sales!$Z:$Z,"0")-K35-U35 -> 0 | X35: {=_xlfn.XLOOKUP($A35,Sales!$A:$A,Sales!$T:$T+Sales!$U:$U+Sales!$V:$V,"0")-K35} -> 0 | Y35: =_xlfn.XLOOKUP($A35,Sales!$A:$A,Sales!$AJ:$AJ,"0") -> 0 | Z35: =_xlfn.XLOOKUP($A35,Sales!$A:$A,Sales!$AL:$AL,"0") -> 0 | AA35: =_xlfn.XLOOKUP($A35,Sales!$A:$A,Sales!$AO:$AO,"0") -> 0 | AB35: =O35+P35+Q35+S35 -> 0 | AC35: =O35+P35+Q35+R35+S35+V35+W35+Y35+Z35+AA35+U35 -> 0 | AD35: =N35-AC35 -> 0 | AE35: =_xlfn.XLOOKUP($A35,Sales!$A:$A,Sales!$Q:$Q,"0") -> 0 | AG35: 36225 | AH35: =VLOOKUP(AG35,Sales!A:V,20,FALSE) -> #N/A | AI35: =VLOOKUP(AG35,Sales!A:U,21,FALSE) -> #N/A | AJ35: =VLOOKUP(AG35,Sales!A:V,22,FALSE) -> #N/A | AK35: =VLOOKUP(AG35,Sales!A:Q,17,FALSE) -> #N/A | AL35: =SUMIF(A:A,AG35,W:W) -> 0
A36: 36433 | C36: =_xlfn.XLOOKUP($A36,Sales!$A:$A,Sales!$D:$D,"0") -> 0 | D36: =SUM(H36+F36+E36-Z36,"0") -> 0 | E36: =_xlfn.XLOOKUP($A36,Sales!$A:$A,Sales!$G:$G,"0") -> 0 | F36: =_xlfn.XLOOKUP($A36,Sales!$A:$A,Sales!$F:$F,"0") -> 0 | G36: =_xlfn.XLOOKUP($A36,Sales!$A:$A,Sales!$AP:$AP,"0") -> 0 | H36: =_xlfn.XLOOKUP($A36,Sales!$A:$A,Sales!$C:$C,"0") -> 0 | I36: =C36 -> 0 | J36: =_xlfn.XLOOKUP($A36,Sales!$A:$A,Sales!$J:$J,"0") -> 0 | K36: =_xlfn.XLOOKUP($A36,Sales!$A:$A,Sales!$H:$H,"0") -> 0 | L36: 0 | M36: =_xlfn.XLOOKUP($A36,Sales!$A:$A,Sales!$AP:$AP,"0") -> 0 | N36: =H36+I36+J36+M36+L36-K36 -> 0 | O36: =_xlfn.XLOOKUP($A36,Sales!$A:$A,Sales!$L:$L,"0") -> 0 | P36: =_xlfn.XLOOKUP($A36,Sales!$A:$A,Sales!$M:$M,"0") -> 0 | Q36: =_xlfn.XLOOKUP($A36,Sales!$A:$A,Sales!$N:$N,"0") -> 0 | R36: =_xlfn.XLOOKUP($A36,Sales!$A:$A,Sales!$O:$O,"0") -> 0 | S36: =_xlfn.XLOOKUP($A36,Sales!$A:$A,Sales!$P:$P,"0") -> 0 | V36: =_xlfn.XLOOKUP($A36,Sales!$A:$A,Sales!$I:$I,"0")*-1 -> 0 | W36: =_xlfn.XLOOKUP($A36,Sales!$A:$A,Sales!$Z:$Z,"0")-K36-U36 -> 0 | X36: {=_xlfn.XLOOKUP($A36,Sales!$A:$A,Sales!$T:$T+Sales!$U:$U+Sales!$V:$V,"0")-K36} -> 0 | Y36: =_xlfn.XLOOKUP($A36,Sales!$A:$A,Sales!$AJ:$AJ,"0") -> 0 | Z36: =_xlfn.XLOOKUP($A36,Sales!$A:$A,Sales!$AL:$AL,"0") -> 0 | AA36: =_xlfn.XLOOKUP($A36,Sales!$A:$A,Sales!$AO:$AO,"0") -> 0 | AB36: =O36+P36+Q36+S36 -> 0 | AC36: =O36+P36+Q36+R36+S36+V36+W36+Y36+Z36+AA36+U36 -> 0 | AD36: =N36-AC36 -> 0 | AE36: =_xlfn.XLOOKUP($A36,Sales!$A:$A,Sales!$Q:$Q,"0") -> 0 | AG36: 36433 | AM36: =AL36-(AH36+AI36+AJ36)+AK36 -> 0
